Workbook

Sheet 文档规模及工作量估计ok
A1: 项目名称 | C1: XXX | G1: 项目编号 | I1: ZDPX03012 | M1: 项目名称 | O1: XXX | S1: 项目编号 | U1: ZDPX03012
A2: 估计人 | B2: 穆笑岩 | D2: 估计类别 | F2: ■规模 ■工作量 | I2: 估计轮次 | K2: 1 | M2: 估计人 | N2: 高蕾 | P2: 估计类别 | R2: ■规模 ■工作量 | U2: 估计轮次 | W2: 1
A3: 估计方法 | D3: 专家估计法 | M3: 估计方法 | P3: 专家估计法
A4: 估计假设和约束条件 | D4: 文档规模估计基于： 1）文档假设采用公司模板编写，页面设置为A4，字号为小四； 2）出所测试文档假设按照配置项测试文档模板编写； 3）文档规模包含封面在内的所有页； 4）参考软件研制任务书的功能数量； 5）参考XXXXXX项目； 6）专家法估计偏差阈值按20%考虑。 | M4: 估计假设和约束条件 | P4: 文档规模估计基于： 1）文档假设采用公司模板编写，页面设置为A4，字号为小四； 2）出所测试文档假设按照配置项测试文档模板编写； 3）文档规模包含封面在内的所有页； 4）参考软件研制任务书的功能数量； 5）参考XXXXXX项目； 6）专家法估计偏差阈值按20%考虑。
D5: 文档编写工作量和合格性测试工作量基于： 1）文档编写人员均有同类文档的编写经验，掌握438C军用软件文档编写要求； 2）参考文档估计规模； 3）参考XXXXXX项目； 4）专家法估计偏差阈值按20%考虑。 | P5: 文档编写工作量和合格性测试工作量基于： 1）文档编写人员均有同类文档的编写经验，掌握438C军用软件文档编写要求； 2）参考文档估计规模； 3）参考XXXXXX项目； 4）专家法估计偏差阈值按20%考虑。
A6: 序号 | B6: 估计对象 | F6: 度量 单位 | G6: 估计值 | L6: 备注 | M6: 序号 | N6: 估计对象 | R6: 度量 单位 | S6: 估计值 | X6: 备注
G7: 总值 | H7: 新增规模 | J7: 重用规模 | S7: 总值 | T7: 新增规模 | V7: 重用规模
A8: 1 | B8: 软件开发计划 | F8: 页 | G8: =H8+J8 -> 35 | H8: 35 | J8: 0 | M8: 1 | N8: 软件开发计划 | R8: 页 | S8: =T8+V8 -> 35 | T8: 35 | V8: 0
A9: 2 | B9: 软件质量保证计划 | F9: 页 | G9: =H9+J9 -> 17 | H9: 17 | J9: 0 | M9: 2 | N9: 软件质量保证计划 | R9: 页 | S9: =T9+V9 -> 14 | T9: 14 | V9: 0
A10: 3 | B10: 软件配置管理计划 | F10: 页 | G10: =H10+J10 -> 15 | H10: 15 | J10: 0 | M10: 3 | N10: 软件配置管理计划 | R10: 页 | S10: =T10+V10 -> 15 | T10: 15 | V10: 0
A11: 4 | B11: 测量与分析计划 | F11: 页 | G11: =H11+J11 -> 11 | H11: 11 | J11: 0 | M11: 4 | N11: 测量与分析计划 | R11: 页 | S11: =T11+V11 -> 11 | T11: 11 | V11: 0
A12: 5 | B12: 需求规格说明 | F12: 页 | G12: =H12+J12 -> 50 | H12: 50 | J12: 0 | M12: 5 | N12: 需求规格说明 | R12: 页 | S12: 55 | T12: 55 | V12: 0
A13: 6 | B13: 配置项测试计划 | F13: 页 | G13: =H13+J13 -> 20 | H13: 20 | J13: 0 | M13: 6 | N13: 配置项测试计划 | R13: 页 | S13: =T13+V13 -> 17 | T13: 17 | V13: 0
A14: 7 | B14: 软件设计说明 | F14: 页 | G14: 100 | H14: 100 | J14: 0 | M14: 7 | N14: 软件设计说明 | R14: 页 | S14: =T14+V14 -> 90 | T14: 90 | V14: 0
A15: 8 | B15: 单元测试计划 | F15: 页 | G15: =H15+J15 -> 0 | J15: 0 | M15: 8 | N15: 单元测试计划 | R15: 页 | S15: =T15+V15 -> 0 | V15: 0
A16: 9 | B16: 单元测试报告 | F16: 页 | G16: =H16+J16 -> 0 | J16: 0 | M16: 9 | N16: 单元测试报告 | R16: 页 | S16: =T16+V16 -> 0 | V16: 0
A17: 10 | B17: 配置项测试说明 | F17: 页 | G17: 40 | H17: 40 | J17: 0 | M17: 10 | N17: 配置项测试说明 | R17: 页 | S17: =T17+V17 -> 40 | T17: 40 | V17: 0
A18: 11 | B18: 配置项测试报告 | F18: 页 | G18: 70 | H18: 70 | J18: 0 | M18: 11 | N18: 配置项测试报告 | R18: 页 | S18: 70 | T18: 70 | V18: 0
A19: 12 | B19: 用户手册 | F19: 页 | G19: =H19+J19 -> 30 | H19: 30 | J19: 0 | M19: 12 | N19: 用户手册 | R19: 页 | S19: =T19+V19 -> 30 | T19: 30 | V19: 0
A20: 13 | B20: 研制总结报告 | F20: 页 | G20: =H20+J20 -> 0 | J20: 0 | M20: 13 | N20: 研制总结报告 | R20: 页 | S20: =T20+V20 -> 0 | V20: 0
A21: 14 | B21: 软件开发计划编写 | F21: 人时 | G21: 12 | H21: — | J21: — | M21: 14 | N21: 软件开发计划编写 | R21: 人时 | S21: 12 | T21: — | V21: —
A22: 15 | B22: 软件质量保证计划编写 | F22: 人时 | G22: 6 | H22: — | J22: — | M22: 15 | N22: 软件质量保证计划编写 | R22: 人时 | S22: 6 | T22: — | V22: —
A23: 16 | B23: 软件配置管理计划编写 | F23: 人时 | G23: 6 | H23: — | J23: — | M23: 16 | N23: 软件配置管理计划编写 | R23: 人时 | S23: 6 | T23: — | V23: —
A24: 17 | B24: 测量与分析计划编写 | F24: 人时 | G24: 6 | H24: — | J24: — | M24: 17 | N24: 测量与分析计划编写 | R24: 人时 | S24: 6 | T24: — | V24: —
A25: 18 | B25: 需求规格说明编写 | F25: 人时 | G25: 45 | H25: — | J25: — | M25: 18 | N25: 需求规格说明编写 | R25: 人时 | S25: 45 | T25: — | V25: —
A26: 19 | B26: 配置项测试计划 | F26: 人时 | G26: 6 | H26: — | J26: — | M26: 19 | N26: 配置项测试计划 | R26: 人时 | S26: 6 | T26: — | V26: —
A27: 20 | B27: 软件设计说明编写 | F27: 人时 | G27: 100 | H27: — | J27: — | M27: 20 | N27: 软件设计说明编写 | R27: 人时 | S27: 100 | T27: — | V27: —
A28: 21 | B28: 单元测试计划编写 | F28: 人时 | G28: 6 | H28: — | J28: — | M28: 21 | N28: 单元测试计划编写 | R28: 人时 | S28: 6 | T28: — | V28: —
A29: 22 | B29: 单元测试报告编写 | F29: 人时 | G29: 6 | H29: — | J29: — | M29: 22 | N29: 单元测试报告编写 | R29: 人时 | S29: 6 | T29: — | V29: —
A30: 23 | B30: 配置项测试说明编写 | F30: 人时 | G30: 40 | H30: — | J30: — | M30: 23 | N30: 配置项测试说明编写 | R30: 人时 | S30: 40 | T30: — | V30: —
A31: 24 | B31: 配置项测试报告编写 | F31: 人时 | G31: 8 | H31: — | J31: — | M31: 24 | N31: 配置项测试报告编写 | R31: 人时 | S31: 8 | T31: — | V31: —
A32: 25 | B32: 用户手册编写 | F32: 人时 | G32: 20 | H32: — | J32: — | M32: 25 | N32: 用户手册编写 | R32: 人时 | S32: 20 | T32: — | V32: —
... A35: 28 | B35: 执行单元测试 | F35: 人时 | G35: 40 | H35: — | J35: — | M35: 28 | N35: 执行单元测试 | R35: 人时 | S35: 35 | T35: — | V35: —
A36: 说明： 1）当估计类别选择“工作量”时，只需填写总值一栏； 2）当估计类别选择“规模”时，总值=新增规模+重用规模； 3）规模的度量单位为“行”（代码）或“页”（文档），工作量为人时； 4）估计对象中，各软件模块应能对应到软件研制任务书中的功能点； 5）“估计假设和约束条件”一栏应说明用于参考的软件研制任务书、类似项目信息、其他可能有用的相关信息； 6）重用包括在原有基础上修改使用和直接使用 | M36: 说明： 1）当估计类别选择“工作量”时，只需填写总值一栏； 2）当估计类别选择“规模”时，总值=新增规模+重用规模； 3）规模的度量单位为“行”（代码）或“页”（文档），工作量为人时； 4）估计对象中，各软件模块应能对应到软件研制任务书中的功能点； 5）“估计假设和约束条件”一栏应说明用于参考的软件研制任务书、类似项目信息、其他可能有用的相关信息； 6）重用包括在原有基础上修改使用和直接使用
A43: 项目名称 | C43: XXX | G43: 项目编号 | I43: ZDPX03012 | M43: 项目名称 | O43: XXX | S43: 项目编号 | U43: ZDPX03012
A44: 估计人 | B44: 张晓丰 | D44: 估计类别 | F44: ■规模 ■工作量 | I44: 估计轮次 | K44: 1 | M44: 估计人 | N44: 方小娟 | P44: 估计类别 | R44: ■规模 ■工作量 | U44: 估计轮次 | W44: 1
A45: 估计方法 | D45: 专家估计法 | M45: 估计方法 | P45: 专家估计法
A46: 估计假设和约束条件 | D46: 文档规模估计基于： 1）文档假设采用公司模板编写，页面设置为A4，字号为小四； 2）出所测试文档假设按照配置项测试文档模板编写； 3）文档规模包含封面在内的所有页； 4）参考软件研制任务书的功能数量； 5）参考XXXXXX项目； 6）专家法估计偏差阈值按20%考虑。 | M46: 估计假设和约束条件 | P46: 文档规模估计基于： 1）文档假设采用公司模板编写，页面设置为A4，字号为小四； 2）出所测试文档假设按照配置项测试文档模板编写； 3）文档规模包含封面在内的所有页； 4）参考软件研制任务书的功能数量； 5）参考XXXXXX项目； 6）专家法估计偏差阈值按20%考虑。
D47: 文档编写工作量和合格性测试工作量基于： 1）文档编写人员均有同类文档的编写经验，掌握438C军用软件文档编写要求； 2）参考文档估计规模； 3）参考XXXXXX项目； 4）专家法估计偏差阈值按20%考虑。 | P47: 文档编写工作量和合格性测试工作量基于： 1）文档编写人员均有同类文档的编写经验，掌握438C军用软件文档编写要求； 2）参考文档估计规模； 3）参考XXXXXX项目； 4）专家法估计偏差阈值按20%考虑。
A48: 序号 | B48: 估计对象 | F48: 度量 单位 | G48: 估计值 | L48: 备注 | M48: 序号 | N48: 估计对象 | R48: 度量 单位 | S48: 估计值 | X48: 备注
...

Sheet 代码规模及工作量估计
A1: 项目名称 | C1: XXX | G1: 项目编号 | I1: ZDPX03012 | M1: 项目名称 | O1: XXX | S1: 项目编号 | U1: ZDPX03012
A2: 估计人 | B2: 穆笑岩 | D2: 估计类别 | F2: ■规模 ■工作量 | I2: 估计轮次 | K2: 1 | M2: 估计人 | N2: 张晓丰 | P2: 估计类别 | R2: ■规模 ■工作量 | U2: 估计轮次 | W2: 1
A3: 估计方法 | D3: 专家估计法 | M3: 估计方法 | P3: 专家估计法
A4: 估计假设和约束条件 | D4: 代码规模估计基于： 1）软件源代码的度量按源代码行（LOC）计算，只考虑有效代码行，不考虑注释。 2）软件采用B/S架构，国产化麒麟系统和达梦数据库，代码编写采用C++、Java和JS语言，使用微软VS Code和IDEA开发工具； 3）参考XXXXXX的开发经验和规模经验； 4）参考软件研制任务书中的功能点数量； 5）只对可能发生变化或新增的软件工作产品进行估计。 6）专家法估计偏差阈值按20%考虑。 | M4: 估计假设和约束条件 | P4: 代码规模估计基于： 1）软件源代码的度量按源代码行（LOC）计算，只考虑有效代码行，不考虑注释。 2）软件采用B/S架构，国产化麒麟系统和达梦数据库，代码编写采用C++、Java和JS语言，使用微软VS Code和IDEA开发工具； 3）参考XXXXXX的开发经验和规模经验； 4）参考软件研制任务书中的功能点数量； 5）只对可能发生变化或新增的软件工作产品进行估计。 6）专家法估计偏差阈值按20%考虑。
D5: 编码、单元测试及软件BUG修改的工作量估计基于： 1）编码人员均有仿真类和评估类项目的开发经验，且熟悉B/S架构的开发模式； 2）参考XXXXXX和XXXXXX中期评估项目的开发经验和规模经验； 3）参考代码估计规模； 4）专家法估计偏差阈值按20%考虑。 | P5: 编码、单元测试及软件BUG修改的工作量估计基于： 1）编码人员均有仿真类和评估类项目的开发经验，且熟悉B/S架构的开发模式； 2）参考XXXXXX和XXXXXX中期评估项目的开发经验和规模经验； 3）参考代码估计规模； 4）专家法估计偏差阈值按20%考虑。
A6: 序号 | B6: 估计对象 | F6: 度量 单位 | G6: 估计值 | L6: 备注 | M6: 序号 | N6: 估计对象 | R6: 度量 单位 | S6: 估计值 | X6: 备注
G7: 总值 | H7: 新增规模 | J7: 重用规模 | S7: 总值 | T7: 新增规模 | V7: 重用规模
A8: 24 | B8: 1 | F8: 行 | G8: 2200 | H8: 2200 | I8: 500 | J8: 0 | M8: 24 | N8: 1 | R8: 行 | S8: 1800 | T8: 1800 | U8: 400 | V8: 0
A9: 25 | B9: 2 | F9: 行 | G9: 9000 | H9: 9000 | I9: 500 | J9: 0 | M9: 25 | N9: 2 | R9: 行 | S9: 8500 | T9: 8500 | U9: 400 | V9: 0
A10: 26 | B10: 3 | F10: 行 | G10: 15000 | H10: 15000 | I10: 500 | J10: 0 | M10: 26 | N10: 3 | R10: 行 | S10: 12000 | T10: 12000 | U10: 400 | V10: 0
A11: 27 | B11: 4 | F11: 行 | G11: 4000 | H11: 4000 | I11: 500 | J11: 0 | M11: 27 | N11: 4 | R11: 行 | S11: 3800 | T11: 3800 | U11: 400 | V11: 0
A12: 30 | B12: 1代码实现 | F12: 人时 | G12: =ROUNDUP(G8/40,0) -> 55 | H12: — | M12: 30 | N12: 1代码实现 | R12: 人时 | S12: =ROUNDUP(S8/40,0) -> 45 | T12: —
A13: 31 | B13: 2代码实现 | F13: 人时 | G13: =ROUNDUP(G9/60,0) -> 150 | H13: — | M13: 31 | N13: 2代码实现 | R13: 人时 | S13: =ROUNDUP(S9/60,0) -> 142 | T13: —
A14: 31 | B14: 3代码实现 | F14: 人时 | G14: =ROUNDUP(G10/60,0) -> 250 | H14: — | M14: 31 | N14: 3代码实现 | R14: 人时 | S14: =ROUNDUP(S10/60,0) -> 200 | T14: —
A15: 32 | B15: 4代码实现 | F15: 人时 | G15: =ROUNDUP(G11/60,0) -> 67 | H15: — | M15: 32 | N15: 4代码实现 | R15: 人时 | S15: =ROUNDUP(S11/60,0) -> 64 | T15: —
A16: 30 | B16: 合格性测试bug修改 | F16: 人时 | G16: 36 | H16: — | M16: 30 | N16: 合格性测试bug修改 | R16: 人时 | S16: 45 | T16: —
A17: 说明： 1）当估计类别选择“工作量”时，只需填写总值一栏； 2）当估计类别选择“规模”时，总值=新增规模+重用规模； 3）规模的度量单位为“行”（代码）或“页”（文档），工作量为人时； 4）估计对象中，各软件模块应能对应到软件研制任务书中的功能点； 5）“估计假设和约束条件”一栏应说明用于参考的软件研制任务书、类似项目信息、其他可能有用的相关信息； 6）重用包括在原有基础上修改使用和直接使用。 | M17: 说明： 1）当估计类别选择“工作量”时，只需填写总值一栏； 2）当估计类别选择“规模”时，总值=新增规模+重用规模； 3）规模的度量单位为“行”（代码）或“页”（文档），工作量为人时； 4）估计对象中，各软件模块应能对应到软件研制任务书中的功能点； 5）“估计假设和约束条件”一栏应说明用于参考的软件研制任务书、类似项目信息、其他可能有用的相关信息； 6）重用包括在原有基础上修改使用和直接使用
A25: 项目名称 | C25: XXX | G25: 项目编号 | I25: ZDPX03012 | M25: 项目名称 | O25: XXX | S25: 项目编号 | U25: ZDPX03012
A26: 估计人 | B26: 刁鹏 | D26: 估计类别 | F26: ■规模 ■工作量 | I26: 估计轮次 | K26: 1 | M26: 估计人 | N26: 孙贵磊 | P26: 估计类别 | R26: ■规模 ■工作量 | U26: 估计轮次 | W26: 1
A27: 估计方法 | D27: 专家估计法 | M27: 估计方法 | P27: 专家估计法
A28: 估计假设和约束条件 | D28: 代码规模估计基于： 1）软件源代码的度量按源代码行（LOC）计算，只考虑有效代码行，不考虑注释。 2）软件采用B/S架构，国产化麒麟系统和达梦数据库，代码编写采用Java和JS语言，使用微软VS Code和IDEA开发工具； 3）参考XXXXXX和XXXXXX中期评估项目的开发经验和规模经验； 4）参考软件研制任务书中的功能点数量； 5）只对可能发生变化或新增的软件工作产品进行估计。 6）专家法估计偏差阈值按20%考虑。 | M28: 估计假设和约束条件 | P28: 代码规模估计基于： 1）软件源代码的度量按源代码行（LOC）计算，只考虑有效代码行，不考虑注释。 2）软件采用B/S架构，国产化麒麟系统和达梦数据库，代码编写采用Java和JS语言，使用微软VS Code和IDEA开发工具； 3）参考XXXXXX和XXXXXX中期评估项目的开发经验和规模经验； 4）参考软件研制任务书中的功能点数量； 5）只对可能发生变化或新增的软件工作产品进行估计。 6）专家法估计偏差阈值按20%考虑。
D29: 编码、单元测试及软件BUG修改的工作量估计基于： 1）编码人员均有仿真类和评估类项目的开发经验，且熟悉B/S架构的开发模式； 2）参考XXXXXX和XXXXXX中期评估项目的开发经验和规模经验； 3）参考代码估计规模； 4）专家法估计偏差阈值按20%考虑。 | P29: 编码、单元测试及软件BUG修改的工作量估计基于： 1）编码人员均有仿真类和评估类项目的开发经验，且熟悉B/S架构的开发模式； 2）参考XXXXXX和XXXXXX中期评估项目的开发经验和规模经验； 3）参考代码估计规模； 4）专家法估计偏差阈值按20%考虑。
A30: 序号 | B30: 估计对象 | F30: 度量 单位 | G30: 估计值 | L30: 备注 | M30: 序号 | N30: 估计对象 | R30: 度量 单位 | S30: 估计值 | X30: 备注
G31: 总值 | H31: 新增规模 | J31: 重用规模 | S31: 总值 | T31: 新增规模 | V31: 重用规模
A32: 24 | B32: 1 | F32: 行 | G32: 1800 | H32: 1800 | I32: 600 | J32: 0 | M32: 24 | N32: 1 | R32: 行 | S32: 2000 | T32: 2000 | U32: 500 | V32: 0
A33: 25 | B33: 2 | F33: 行 | G33: 8000 | H33: 8000 | I33: 600 | J33: 0 | M33: 25 | N33: 2 | R33: 行 | S33: 8500 | T33: 8500 | U33: 500 | V33: 0
A34: 26 | B34: 3 | F34: 行 | G34: 13000 | H34: 13000 | I34: 600 | J34: 0 | M34: 26 | N34: 3 | R34: 行 | S34: 14000 | T34: 14000 | U34: 500 | V34: 0
A35: 27 | B35: 4 | F35: 行 | G35: 4000 | H35: 4000 | I35: 600 | J35: 0 | M35: 27 | N35: 4 | R35: 行 | S35: 3500 | T35: 3500 | U35: 500 | V35: 0
A36: 30 | B36: 1代码实现 | F36: 人时 | G36: =ROUNDUP(G32/40,0) -> 45 | H36: — | M36: 30 | N36: 1代码实现 | R36: 人时 | S36: =ROUNDUP(S32/40,0) -> 50 | T36: —
A37: 31 | B37: 2代码实现 | F37: 人时 | G37: =ROUNDUP(G33/60,0) -> 134 | H37: — | M37: 31 | N37: 2代码实现 | R37: 人时 | S37: =ROUNDUP(S33/60,0) -> 142 | T37: —
A38: 31 | B38: 3代码实现 | F38: 人时 | G38: =ROUNDUP(G34/60,0) -> 217 | H38: — | M38: 31 | N38: 3代码实现 | R38: 人时 | S38: =ROUNDUP(S34/60,0) -> 234 | T38: —
A39: 32 | B39: 4代码实现 | F39: 人时 | G39: =ROUNDUP(G35/60,0) -> 67 | H39: — | M39: 32 | N39: 4代码实现 | R39: 人时 | S39: =ROUNDUP(S35/60,0) -> 59 | T39: —
A40: 31 | B40: 合格性测试bug修改 | F40: 人时 | G40: 40 | H40: — | M40: 31 | N40: 合格性测试bug修改 | R40: 人时 | S40: 35 | T40: —
A41: 说明： 1）当估计类别选择“工作量”时，只需填写总值一栏； 2）当估计类别选择“规模”时，总值=新增规模+重用规模； 3）规模的度量单位为“行”（代码）或“页”（文档），工作量为人时； 4）估计对象中，各软件模块应能对应到软件研制任务书中的功能点； 5）“估计假设和约束条件”一栏应说明用于参考的软件研制任务书、类似项目信息、其他可能有用的相关信息； 6）重用包括在原有基础上修改使用和直接使用 | M41: 说明： 1）当估计类别选择“工作量”时，只需填写总值一栏； 2）当估计类别选择“规模”时，总值=新增规模+重用规模； 3）规模的度量单位为“行”（代码）或“页”（文档），工作量为人时； 4）估计对象中，各软件模块应能对应到软件研制任务书中的功能点； 5）“估计假设和约束条件”一栏应说明用于参考的软件研制任务书、类似项目信息、其他可能有用的相关信息； 6）重用包括在原有基础上修改使用和直接使用

Sheet 汇总表(文档相关)ok
A1: 项目名称 | B1: XXX | I1: 项目编号 | K1: ZDPX2021163
A2: 估计人 | B2: =文档规模及工作量估计ok!B2&文档规模及工作量估计ok!N2&文档规模及工作量估计ok!B44&文档规模及工作量估计ok!N44 -> 穆笑岩高蕾 张晓丰方小娟 | F2: 估计类别 | G2: ■规模 ■工作量 | L2: 估计轮次
A3: 估计方法 | D3: =文档规模及工作量估计ok!D45 -> 专家估计法
A4: 估计假设和约束条件 | E4: =文档规模及工作量估计ok!D46 -> 文档规模估计基于： 1）文档假设采用公司模板编写，页面设置为A4，字号为小四； 2）出所测试文档假设按照配置项测试文档模板编写； 3）文档规模包含封面在内的所有页； 4）参考软件研制任务书的功能数量； 5）参考XXXXXX项目； 6）专家法估计偏差阈值按20%考虑。
E5: =文档规模及工作量估计ok!D47 -> 文档编写工作量和合格性测试工作量基于： 1）文档编写人员均有同类文档的编写经验，掌握438C军用软件文档编写要求； 2）参考文档估计规模； 3）参考XXXXXX项目； 4）专家法估计偏差阈值按20%考虑。
A6: 序号 | B6: 估计对象 | F6: 度量单位 | H6: 估计值 | M6: 估计值 取整
H7: 平均 | J7: 最大 | K7: 最小 | L7: 偏差率
A8: 1 | B8: =文档规模及工作量估计ok!B8 -> 软件开发计划 | F8: 页 | H8: =(文档规模及工作量估计ok!G8+文档规模及工作量估计ok!S8+文档规模及工作量估计ok!G50+文档规模及工作量估计ok!S50)/4 -> 35 | J8: =MAX(文档规模及工作量估计ok!G50,文档规模及工作量估计ok!S50,文档规模及工作量估计ok!G8,文档规模及工作量估计ok!S8) -> 35 | K8: =MIN(文档规模及工作量估计ok!G8,文档规模及工作量估计ok!S8,文档规模及工作量估计ok!G50,文档规模及工作量估计ok!S50) -> 35 | L8: =MAX(ABS(J8-H8),ABS(K8-H8))/H8 -> 0 | M8: =ROUND(H8,0) -> 35
A9: 2 | B9: =文档规模及工作量估计ok!B9 -> 软件质量保证计划 | F9: 页 | H9: =(文档规模及工作量估计ok!G9+文档规模及工作量估计ok!S9+文档规模及工作量估计ok!G51+文档规模及工作量估计ok!S51)/4 -> 15.75 | J9: =MAX(文档规模及工作量估计ok!G51,文档规模及工作量估计ok!S51,文档规模及工作量估计ok!G9,文档规模及工作量估计ok!S9) -> 17 | K9: =MIN(文档规模及工作量估计ok!G9,文档规模及工作量估计ok!S9,文档规模及工作量估计ok!G51,文档规模及工作量估计ok!S51) -> 14 | L9: =MAX(ABS(J9-H9),ABS(K9-H9))/H9 -> 0.11111111 | M9: =ROUND(H9,0) -> 16
A10: 3 | B10: =文档规模及工作量估计ok!B10 -> 软件配置管理计划 | F10: 页 | H10: =(文档规模及工作量估计ok!G10+文档规模及工作量估计ok!S10+文档规模及工作量估计ok!G52+文档规模及工作量估计ok!S52)/4 -> 14.25 | J10: =MAX(文档规模及工作量估计ok!G52,文档规模及工作量估计ok!S52,文档规模及工作量估计ok!G10,文档规模及工作量估计ok!S10) -> 15 | K10: =MIN(文档规模及工作量估计ok!G10,文档规模及工作量估计ok!S10,文档规模及工作量估计ok!G52,文档规模及工作量估计ok!S52) -> 13 | L10: =MAX(ABS(J10-H10),ABS(K10-H10))/H10 -> 0.087719298 | M10: =ROUND(H10,0) -> 14
A11: 4 | B11: =文档规模及工作量估计ok!B11 -> 测量与分析计划 | F11: 页 | H11: =(文档规模及工作量估计ok!G11+文档规模及工作量估计ok!S11+文档规模及工作量估计ok!G53+文档规模及工作量估计ok!S53)/4 -> 11 | J11: =MAX(文档规模及工作量估计ok!G53,文档规模及工作量估计ok!S53,文档规模及工作量估计ok!G11,文档规模及工作量估计ok!S11) -> 11 | K11: =MIN(文档规模及工作量估计ok!G11,文档规模及工作量估计ok!S11,文档规模及工作量估计ok!G53,文档规模及工作量估计ok!S53) -> 11 | L11: =MAX(ABS(J11-H11),ABS(K11-H11))/H11 -> 0 | M11: =ROUND(H11,0) -> 11
A12: 5 | B12: =文档规模及工作量估计ok!B12 -> 需求规格说明 | F12: 页 | H12: =(文档规模及工作量估计ok!G12+文档规模及工作量估计ok!S12+文档规模及工作量估计ok!G54+文档规模及工作量估计ok!S54)/4 -> 55 | J12: =MAX(文档规模及工作量估计ok!G54,文档规模及工作量估计ok!S54,文档规模及工作量估计ok!G12,文档规模及工作量估计ok!S12) -> 60 | K12: =MIN(文档规模及工作量估计ok!G12,文档规模及工作量估计ok!S12,文档规模及工作量估计ok!G54,文档规模及工作量估计ok!S54) -> 50 | L12: =MAX(ABS(J12-H12),ABS(K12-H12))/H12 -> 0.090909091 | M12: =ROUND(H12,0) -> 55
A13: 6 | B13: =文档规模及工作量估计ok!B13 -> 配置项测试计划 | F13: 页 | H13: =(文档规模及工作量估计ok!G13+文档规模及工作量估计ok!S13+文档规模及工作量估计ok!G55+文档规模及工作量估计ok!S55)/4 -> 18 | J13: =MAX(文档规模及工作量估计ok!G55,文档规模及工作量估计ok!S55,文档规模及工作量估计ok!G13,文档规模及工作量估计ok!S13) -> 20 | K13: =MIN(文档规模及工作量估计ok!G13,文档规模及工作量估计ok!S13,文档规模及工作量估计ok!G55,文档规模及工作量估计ok!S55) -> 15 | L13: =MAX(ABS(J13-H13),ABS(K13-H13))/H13 -> 0.16666667 | M13: =ROUND(H13,0) -> 18
A14: 7 | B14: =文档规模及工作量估计ok!B14 -> 软件设计说明 | F14: 页 | H14: =(文档规模及工作量估计ok!G14+文档规模及工作量估计ok!S14+文档规模及工作量估计ok!G56+文档规模及工作量估计ok!S56)/4 -> 90 | J14: =MAX(文档规模及工作量估计ok!G56,文档规模及工作量估计ok!S56,文档规模及工作量估计ok!G14,文档规模及工作量估计ok!S14) -> 100 | K14: =MIN(文档规模及工作量估计ok!G14,文档规模及工作量估计ok!S14,文档规模及工作量估计ok!G56,文档规模及工作量估计ok!S56) -> 80 | L14: =MAX(ABS(J14-H14),ABS(K14-H14))/H14 -> 0.11111111 | M14: =ROUND(H14,0) -> 90
A15: 8 | B15: =文档规模及工作量估计ok!B15 -> 单元测试计划 | F15: 页 | H15: =(文档规模及工作量估计ok!G15+文档规模及工作量估计ok!S15+文档规模及工作量估计ok!G57+文档规模及工作量估计ok!S57)/4 -> 0 | J15: =MAX(文档规模及工作量估计ok!G57,文档规模及工作量估计ok!S57,文档规模及工作量估计ok!G15,文档规模及工作量估计ok!S15) -> 0 | K15: =MIN(文档规模及工作量估计ok!G15,文档规模及工作量估计ok!S15,文档规模及工作量估计ok!G57,文档规模及工作量估计ok!S57) -> 0 | L15: =MAX(ABS(J15-H15),ABS(K15-H15))/H15 -> #DIV/0! | M15: =ROUND(H15,0) -> 0
A16: 13 | B16: =文档规模及工作量估计ok!B16 -> 单元测试报告 | F16: 页 | H16: =(文档规模及工作量估计ok!G16+文档规模及工作量估计ok!S16+文档规模及工作量估计ok!G58+文档规模及工作量估计ok!S58)/4 -> 0 | J16: =MAX(文档规模及工作量估计ok!G58,文档规模及工作量估计ok!S58,文档规模及工作量估计ok!G16,文档规模及工作量估计ok!S16) -> 0 | K16: =MIN(文档规模及工作量估计ok!G16,文档规模及工作量估计ok!S16,文档规模及工作量估计ok!G58,文档规模及工作量估计ok!S58) -> 0 | L16: =MAX(ABS(J16-H16),ABS(K16-H16))/H16 -> #DIV/0! | M16: =ROUND(H16,0) -> 0
A17: 15 | B17: =文档规模及工作量估计ok!B17 -> 配置项测试说明 | F17: 页 | H17: =(文档规模及工作量估计ok!G17+文档规模及工作量估计ok!S17+文档规模及工作量估计ok!G59+文档规模及工作量估计ok!S59)/4 -> 42.5 | J17: =MAX(文档规模及工作量估计ok!G59,文档规模及工作量估计ok!S59,文档规模及工作量估计ok!G17,文档规模及工作量估计ok!S17) -> 45 | K17: =MIN(文档规模及工作量估计ok!G17,文档规模及工作量估计ok!S17,文档规模及工作量估计ok!G59,文档规模及工作量估计ok!S59) -> 40 | L17: =MAX(ABS(J17-H17),ABS(K17-H17))/H17 -> 0.058823529 | M17: =ROUND(H17,0) -> 43
A18: 16 | B18: =文档规模及工作量估计ok!B18 -> 配置项测试报告 | F18: 页 | H18: =(文档规模及工作量估计ok!G18+文档规模及工作量估计ok!S18+文档规模及工作量估计ok!G60+文档规模及工作量估计ok!S60)/4 -> 72.5 | J18: =MAX(文档规模及工作量估计ok!G60,文档规模及工作量估计ok!S60,文档规模及工作量估计ok!G18,文档规模及工作量估计ok!S18) -> 80 | K18: =MIN(文档规模及工作量估计ok!G18,文档规模及工作量估计ok!S18,文档规模及工作量估计ok!G60,文档规模及工作量估计ok!S60) -> 70 | L18: =MAX(ABS(J18-H18),ABS(K18-H18))/H18 -> 0.10344828 | M18: =ROUND(H18,0) -> 73
A19: 17 | B19: =文档规模及工作量估计ok!B19 -> 用户手册 | F19: 页 | H19: =(文档规模及工作量估计ok!G19+文档规模及工作量估计ok!S19+文档规模及工作量估计ok!G61+文档规模及工作量估计ok!S61)/4 -> 30 | J19: =MAX(文档规模及工作量估计ok!G61,文档规模及工作量估计ok!S61,文档规模及工作量估计ok!G19,文档规模及工作量估计ok!S19) -> 30 | K19: =MIN(文档规模及工作量估计ok!G19,文档规模及工作量估计ok!S19,文档规模及工作量估计ok!G61,文档规模及工作量估计ok!S61) -> 30 | L19: =MAX(ABS(J19-H19),ABS(K19-H19))/H19 -> 0 | M19: =ROUND(H19,0) -> 30
... A35: 42 | B35: =文档规模及工作量估计ok!B35 -> 执行单元测试 | F35: 人时 | H35: =(文档规模及工作量估计ok!G35+文档规模及工作量估计ok!S35+文档规模及工作量估计ok!G77+文档规模及工作量估计ok!S77)/4 -> 36.25 | J35: =MAX(文档规模及工作量估计ok!G77,文档规模及工作量估计ok!S77,文档规模及工作量估计ok!G35,文档规模及工作量估计ok!S35) -> 40 | K35: =MIN(文档规模及工作量估计ok!G35,文档规模及工作量估计ok!S35,文档规模及工作量估计ok!G77,文档规模及工作量估计ok!S77) -> 35 | L35: =MAX(ABS(J35-H35),ABS(K35-H35))/H35 -> 0.10344828 | M35: =ROUND(H35,0) -> 36
A36: 说明： 1）该表按照估计类别分别汇总每个估计人员填写的估计表（附录A）； 2）估计值“最大”和“最小”取自附录A的“总值”一栏； 3）规模的度量单位为“行”（代码）或“页”（文档），工作量为人时； 4）“估计假设和约束条件”一栏应说明偏差阈值、用于参考的软件研制任务书、规模数据、类似项目信息、其他可能有用的相关信息。
A43: 工作量与进度安排表
A44: 序号 | B44: 估计对象 | F44: 工作量估计值 | H44: 计划分配资源 | K44: 每日可用 工作时间 | M44: 任务所需工作日
A45: 1 | B45: =B21 -> 软件开发计划编写 | F45: =M21 -> 12 | H45: 穆笑岩 | K45: 4 | M45: =ROUNDUP(F45/K45,0) -> 3
A46: 2 | B46: =B22 -> 软件质量保证计划编写 | F46: =M22 -> 6 | H46: 高蕾 | K46: 6 | M46: =ROUNDUP(F46/K46,0) -> 1
A47: 3 | B47: =B23 -> 软件配置管理计划编写 | F47: =M23 -> 6 | H47: 王令敏 | K47: 6 | M47: =ROUNDUP(F47/K47,0) -> 1
A48: 4 | B48: =B24 -> 测量与分析计划编写 | F48: =M24 -> 6 | H48: 穆笑岩 | K48: 2 | M48: =ROUNDUP(F48/K48,0) -> 3
A49: 5 | B49: =B25 -> 需求规格说明编写 | F49: =M25 -> 48 | H49: 穆笑岩 | K49: 6 | M49: =ROUNDUP(F49/K49,0) -> 8
A50: 6 | B50: =B26 -> 配置项测试计划 | F50: =M26 -> 6 | H50: 方小娟 | K50: 6 | M50: =ROUNDUP(F50/K50,0) -> 1
A51: 7 | B51: =B27 -> 软件设计说明编写 | F51: =M27 -> 96 | H51: 李国荣,孙贵磊,张晓丰 | K51: 12 | M51: =ROUNDUP(F51/K51,0) -> 8
A52: 8 | B52: =B28 -> 单元测试计划编写 | F52: =M28 -> 6 | H52: 李国荣 | K52: 6 | M52: =ROUNDUP(F52/K52,0) -> 1
A53: 9 | B53: =B29 -> 单元测试报告编写 | F53: =M29 -> 6 | H53: 李国荣 | K53: 6 | M53: =ROUNDUP(F53/K53,0) -> 1
A54: 10 | B54: =B30 -> 配置项测试说明编写 | F54: =M30 -> 40 | H54: 方小娟 | K54: 4 | M54: =ROUNDUP(F54/K54,0) -> 10
A55: 11 | B55: =B31 -> 配置项测试报告编写 | F55: =M31 -> 8 | H55: 方小娟、李德馨 | K55: 8 | M55: =ROUNDUP(F55/K55,0) -> 1
A56: 12 | B56: =B32 -> 用户手册编写 | F56: =M32 -> 20 | H56: 李国荣 | K56: 4 | M56: =ROUNDUP(F56/K56,0) -> 5
... A59: 15 | B59: =B35 -> 执行单元测试 | F59: =M35 -> 36 | H59: 李国荣,孙贵磊 | K59: 12 | M59: =ROUNDUP(F59/K59,0) -> 3

Sheet 汇总表(代码相关)
A1: 项目名称 | B1: XXX | I1: 项目编号 | K1: ZDPX03012
A2: 估计人 | B2: =代码规模及工作量估计!B2&代码规模及工作量估计!N2&代码规模及工作量估计!B26&代码规模及工作量估计!N26 -> 穆笑岩张晓丰刁鹏孙贵磊 | F2: 估计类别 | G2: ■规模 ■工作量 | L2: 估计轮次 | N2: =代码规模及工作量估计!K2 -> 1
A3: 估计方法 | D3: =代码规模及工作量估计!D3 -> 专家估计法
A4: 估计假设和约束条件 | E4: =代码规模及工作量估计!D4 -> 代码规模估计基于： 1）软件源代码的度量按源代码行（LOC）计算，只考虑有效代码行，不考虑注释。 2）软件采用B/S架构，国产化麒麟系统和达梦数据库，代码编写采用C++、Java和JS语言，使用微软VS Code和IDEA开发工具； 3）参考XXXXXX的开发经验和规模经验； 4）参考软件研制任务书中的功能点数量； 5）只对可能发生变化或新增的软件工作产品进行估计。 6）专家法估计偏差阈值按20%考虑。
E5: =代码规模及工作量估计!D5 -> 编码、单元测试及软件BUG修改的工作量估计基于： 1）编码人员均有仿真类和评估类项目的开发经验，且熟悉B/S架构的开发模式； 2）参考XXXXXX和XXXXXX中期评估项目的开发经验和规模经验； 3）参考代码估计规模； 4）专家法估计偏差阈值按20%考虑。
A6: 序号 | B6: 估计对象 | F6: 度量单位 | H6: 估计值 | O6: 估计值 取整
H7: 平均 | J7: 最大 | K7: 最小 | M7: 偏差率
A8: 24 | C8: =代码规模及工作量估计!B32 -> 1 | H8: =(代码规模及工作量估计!G8+代码规模及工作量估计!S8+代码规模及工作量估计!G32+代码规模及工作量估计!S32)/4 -> 1950 | J8: =MAX(代码规模及工作量估计!G32,代码规模及工作量估计!S32,代码规模及工作量估计!G8,代码规模及工作量估计!S8) -> 2200 | K8: =MIN(代码规模及工作量估计!G8,代码规模及工作量估计!S8,代码规模及工作量估计!G32,代码规模及工作量估计!S32) -> 1800 | M8: =MAX(ABS(J8-H8),ABS(K8-H8))/H8 -> 0.12820513 | O8: =ROUND(H8,0) -> 1950
A9: 25 | C9: =代码规模及工作量估计!B33 -> 2 | H9: =(代码规模及工作量估计!G9+代码规模及工作量估计!S9+代码规模及工作量估计!G33+代码规模及工作量估计!S33)/4 -> 8500 | J9: =MAX(代码规模及工作量估计!G33,代码规模及工作量估计!S33,代码规模及工作量估计!G9,代码规模及工作量估计!S9) -> 9000 | K9: =MIN(代码规模及工作量估计!G9,代码规模及工作量估计!S9,代码规模及工作量估计!G33,代码规模及工作量估计!S33) -> 8000 | M9: =MAX(ABS(J9-H9),ABS(K9-H9))/H9 -> 0.058823529 | O9: =ROUND(H9,0) -> 8500
A10: 26 | C10: =代码规模及工作量估计!B34 -> 3 | H10: =(代码规模及工作量估计!G10+代码规模及工作量估计!S10+代码规模及工作量估计!G34+代码规模及工作量估计!S34)/4 -> 13500 | J10: =MAX(代码规模及工作量估计!G34,代码规模及工作量估计!S34,代码规模及工作量估计!G10,代码规模及工作量估计!S10) -> 15000 | K10: =MIN(代码规模及工作量估计!G10,代码规模及工作量估计!S10,代码规模及工作量估计!G34,代码规模及工作量估计!S34) -> 12000 | M10: =MAX(ABS(J10-H10),ABS(K10-H10))/H10 -> 0.11111111 | O10: =ROUND(H10,0) -> 13500
A11: 27 | C11: =代码规模及工作量估计!B35 -> 4 | H11: =(代码规模及工作量估计!G11+代码规模及工作量估计!S11+代码规模及工作量估计!G35+代码规模及工作量估计!S35)/4 -> 3825 | J11: =MAX(代码规模及工作量估计!G35,代码规模及工作量估计!S35,代码规模及工作量估计!G11,代码规模及工作量估计!S11) -> 4000 | K11: =MIN(代码规模及工作量估计!G11,代码规模及工作量估计!S11,代码规模及工作量估计!G35,代码规模及工作量估计!S35) -> 3500 | M11: =MAX(ABS(J11-H11),ABS(K11-H11))/H11 -> 0.08496732 | O11: =ROUND(H11,0) -> 3825
A12: 28 | B12: =代码规模及工作量估计!B12 -> 1代码实现 | F12: =代码规模及工作量估计!F12 -> 人时 | H12: =(代码规模及工作量估计!G12+代码规模及工作量估计!S12+代码规模及工作量估计!G36+代码规模及工作量估计!S36)/4 -> 48.75 | J12: =MAX(代码规模及工作量估计!G36,代码规模及工作量估计!S36,代码规模及工作量估计!G12,代码规模及工作量估计!S12) -> 55 | K12: =MIN(代码规模及工作量估计!G12,代码规模及工作量估计!S12,代码规模及工作量估计!G36,代码规模及工作量估计!S36) -> 45 | M12: =MAX(ABS(J12-H12),ABS(K12-H12))/H12 -> 0.12820513 | O12: =ROUND(H12,0) -> 49
A13: 29 | B13: =代码规模及工作量估计!B13 -> 2代码实现 | F13: =代码规模及工作量估计!F13 -> 人时 | H13: =(代码规模及工作量估计!G13+代码规模及工作量估计!S13+代码规模及工作量估计!G37+代码规模及工作量估计!S37)/4 -> 142 | J13: =MAX(代码规模及工作量估计!G37,代码规模及工作量估计!S37,代码规模及工作量估计!G13,代码规模及工作量估计!S13) -> 150 | K13: =MIN(代码规模及工作量估计!G13,代码规模及工作量估计!S13,代码规模及工作量估计!G37,代码规模及工作量估计!S37) -> 134 | M13: =MAX(ABS(J13-H13),ABS(K13-H13))/H13 -> 0.056338028 | O13: =ROUND(H13,0) -> 142
A14: 30 | B14: =代码规模及工作量估计!B14 -> 3代码实现 | F14: =代码规模及工作量估计!F14 -> 人时 | H14: =(代码规模及工作量估计!G14+代码规模及工作量估计!S14+代码规模及工作量估计!G38+代码规模及工作量估计!S38)/4 -> 225.25 | J14: =MAX(代码规模及工作量估计!G38,代码规模及工作量估计!S38,代码规模及工作量估计!G14,代码规模及工作量估计!S14) -> 250 | K14: =MIN(代码规模及工作量估计!G14,代码规模及工作量估计!S14,代码规模及工作量估计!G38,代码规模及工作量估计!S38) -> 200 | M14: =MAX(ABS(J14-H14),ABS(K14-H14))/H14 -> 0.11209767 | O14: =ROUND(H14,0) -> 225
A15: 31 | B15: =代码规模及工作量估计!B15 -> 4代码实现 | F15: =代码规模及工作量估计!F15 -> 人时 | H15: =(代码规模及工作量估计!G15+代码规模及工作量估计!S15+代码规模及工作量估计!G39+代码规模及工作量估计!S39)/4 -> 64.25 | J15: =MAX(代码规模及工作量估计!G39,代码规模及工作量估计!S39,代码规模及工作量估计!G15,代码规模及工作量估计!S15) -> 67 | K15: =MIN(代码规模及工作量估计!G15,代码规模及工作量估计!S15,代码规模及工作量估计!G39,代码规模及工作量估计!S39) -> 59 | M15: =MAX(ABS(J15-H15),ABS(K15-H15))/H15 -> 0.081712062 | O15: =ROUND(H15,0) -> 64
A16: 37 | B16: =代码规模及工作量估计!B16 -> 合格性测试bug修改 | F16: =代码规模及工作量估计!F16 -> 人时 | H16: =(代码规模及工作量估计!G16+代码规模及工作量估计!S16+代码规模及工作量估计!G40+代码规模及工作量估计!S40)/4 -> 39 | J16: =MAX(代码规模及工作量估计!G40,代码规模及工作量估计!S40,代码规模及工作量估计!G16,代码规模及工作量估计!S16) -> 45 | K16: =MIN(代码规模及工作量估计!G16,代码规模及工作量估计!S16,代码规模及工作量估计!G40,代码规模及工作量估计!S40) -> 35 | M16: =MAX(ABS(J16-H16),ABS(K16-H16))/H16 -> 0.15384615 | O16: =ROUND(H16,0) -> 39
A17: 说明： 1）该表按照估计类别分别汇总每个估计人员填写的估计表（附录A）； 2）估计值“最大”和“最小”取自附录A的“总值”一栏； 3）规模的度量单位为“行”（代码）或“页”（文档），工作量为人时； 4）“估计假设和约束条件”一栏应说明偏差阈值、用于参考的软件研制任务书、规模数据、类似项目信息、其他可能有用的相关信息。
A28: 代码工作量与进度安排
A29: 序号 | B29: 估计对象 | F29: 工作量估计值 | H29: 计划分配资源 | K29: 每日可用 工作时间 | O29: 任务所需工作日
A30: 1 | B30: =B12 -> 1代码实现 | F30: =O12 -> 49 | H30: 董薇、孙贵磊 | K30: 10 | O30: =ROUNDUP(F30/K30,0) -> 5
A31: 2 | B31: =B13 -> 2代码实现 | F31: =O13 -> 142 | H31: 董薇、李静静 | K31: 10 | O31: =ROUNDUP(F31/K31,0) -> 15
A32: 3 | B32: =B14 -> 3代码实现 | F32: =O14 -> 225 | H32: 张晓丰、刁鹏、李国荣 | K32: 18 | O32: =ROUNDUP(F32/K32,0) -> 13
A33: 4 | B33: =B15 -> 4代码实现 | F33: =O15 -> 64 | H33: 张晓丰、孙贵磊 | K33: 12 | O33: =ROUNDUP(F33/K33,0) -> 6
A34: 9 | B34: =B16 -> 合格性测试bug修改 | F34: =O16 -> 39 | H34: 刁鹏、孙贵磊 | K34: 10 | O34: =ROUNDUP(F34/K34,0) -> 4

Sheet 配置管理工作量估计ok
A1: 项目名称 | B1: XXX | D1: 项目编号 | E1: ZDPX03012
A2: 估计方法 | B2: 经验法 | D2: 估计人员 | E2: 王令敏
A3: 估计假设与约束条件 | B3: 配置管理活动工作量的估计，基于公司提供的单次活动工时经验数据、项目周期内预计开展的活动次数及配置活动内容计算所得。公司提供的单次活动工时经验值见《软件估计指南》
A4: 估计过程
B5: 阶段时长（月） | C5: 配置管理活动 | D5: 工作量估计 （人时） | E5: 单次活动工时 （人时） | F5: 活动次数
A6: 系统分析与设计阶段 | B6: 1.5 | C6: 出入受控库 | D6: =E6*F6 -> 1 | E6: 1 | F6: 1
C7: 发布基线 | D7: =E7*F7 -> 0.5 | E7: 0.5 | F7: 1
C8: 配置状态纪实 | D8: =E8*F8 -> 0.5 | E8: 0.5 | F8: 1
C9: 配置管理报告 | D9: =E9*F9 -> 0.5 | E9: 0.5 | F9: 1
C10: 合计 | D10: =SUM(D5:D9) -> 2.5
A11: 需求分析阶段 | B11: 1 | C11: 出入受控库 | D11: =E11*F11 -> 3 | E11: 1 | F11: 3
C12: 发布基线 | D12: =E12*F12 -> 0.5 | E12: 0.5 | F12: 1
C13: 配置状态纪实 | D13: =E13*F13 -> 0.5 | E13: 0.5 | F13: 1
C14: 配置管理报告 | D14: =E14*F14 -> 0.5 | E14: 0.5 | F14: 1
C15: 合计 | D15: =SUM(D11:D14) -> 4.5
A16: 软件设计与编码测试阶段 | B16: 1.5 | C16: 出入受控库 | D16: =E16*F16 -> 2.5 | E16: 0.5 | F16: 5
C17: 配置状态纪实 | D17: =E17*F17 -> 1 | E17: 0.5 | F17: 2
C18: 配置管理报告 | D18: =E18*F18 -> 0.5 | E18: 0.5 | F18: 1
C19: 合计 | D19: =SUM(D16:D18) -> 4
A20: 软件合格性测试与验收阶段 | B20: 0.5 | C20: 出入受控库 | D20: =E20*F20 -> 3.5 | E20: 0.5 | F20: 7
C21: 出厂产品基线发布 | D21: =E21*F21 -> 1 | E21: 1 | F21: 1
C22: 配置项变更 | D22: =E22*F22 -> 2 | E22: 1 | F22: 2
C23: 配置状态纪实 | D23: =E23*F23 -> 0.5 | E23: 0.5 | F23: 1
C24: 配置管理报告 | D24: =E24*F24 -> 0.5 | E24: 0.5 | F24: 1
C25: 合计 | D25: =SUM(D20:D24) -> 7.5
A26: 总计 | D26: =D10+D15+D19+D25 -> 18.5

Sheet 质量保证工作量估计ok
A1: 项目名称 | C1: XXX | E1: 项目编号 | F1: ZDPX03012
A2: 估计方法 | C2: 经验法 | E2: 估计人员 | F2: 高蕾
A3: 估计假设和约束条件 | C3: 质量保证活动工作量的估计，基于公司提供的单次活动工时经验数据、项目周期内预计开展的质量活动次数计算所得。公司提供的单次活动工时经验值见《软件估计指南》。
A4: 估计过程
B5: 阶段时长(月) | C5: 质量活动 | D5: 工作量估计 | E5: 单次过程审核工时 | F5: 单次产品审核工时 | G5: 审核次数
A6: 系统分析与设计 | C6: 审核软件研制任务书 | D6: =F6*G6 -> 2 | F6: 2 | G6: 1
C7: 审核需求开发与管理 | D7: =E7*G7 -> 1 | E7: 1 | G7: 1
C8: 审核验证与确认 | D8: =E8*G8 -> 0.5 | E8: 0.5 | G8: 1
C9: 审核配置管理 | D9: =E9*G9 -> 0.5 | E9: 0.5 | G9: 1
C10: 审核领导作用 | D10: =E10*G10 -> 0.5 | E10: 0.5 | G10: 1
C11: 审核实施基础 | D11: =E11*G11 -> 0.5 | E11: 0.5 | G11: 1
C12: 拟制质量审核报告 | D12: =E12*G12 -> 0.5 | E12: 0.5 | G12: 1
C13: 合计 | D13: =SUM(D6:D12) -> 5.5
A14: 需求分析阶段 | C14: 审核项目策划过程 | D14: =E14*G14 -> 1 | E14: 1 | G14: 1
C15: 审核验证与确认-工作产品评审过程 | D15: =E15*G15 -> 0.5 | E15: 0.5 | G15: 1
C16: 审核需求开发与管理 | D16: =E16*G16 -> 1 | E16: 1 | G16: 1
C17: 审核领导作用 | D17: =E17*G17 -> 0.5 | E17: 0.5 | G17: 1
C18: 审核实施基础 | D18: =E18*G18 -> 0.5 | E18: 0.5 | G18: 1
C19: 审核运行维护 | D19: =E19*G19 -> 0.5 | E19: 0.5 | G19: 1
C20: 审核配置管理过程 | D20: =E20*G20 -> 1 | E20: 0.5 | G20: 2
C21: 审核项目监控过程 | D21: =E21*G21 -> 3 | E21: 1 | G21: 3
C22: 审核测量与绩效 | D22: =E22*G22 -> 1.5 | E22: 0.5 | G22: 3
C23: 审核软件开发计划、质量保证计划、测量与分析计划、配置管理计划 | D23: =F23*G23 -> 4 | F23: 4 | G23: 1
C24: 审核需求规格说明 | D24: =F24*G24 -> 4 | F24: 4 | G24: 1
C25: 审核配置项测试计划 | D25: =F25*G25 -> 0.5 | F25: 0.5 | G25: 1
C26: 拟制质量审核报告 | D26: =F26*G26 -> 1.5 | F26: 0.5 | G26: 3
C27: 合计 | D27: =SUM(D14:D26) -> 19.5
A28: 软件概要设计阶段 | C28: 软件概要设计审核 | D28: =F28*G28 -> 2 | F28: 2 | G28: 1
C29: 单元测试计划审核 | D29: =F29*G29 -> 1 | F29: 1 | G29: 1
C30: 审核项目策划过程 | D30: =E30*G30 -> 1 | E30: 1 | G30: 1
C31: 审核测量与绩效 | D31: =E31*G31 -> 1 | E31: 0.5 | G31: 2
C32: 审核项目监控过程 | D32: =E32*G32 -> 2 | E32: 1 | G32: 2
C33: 审核配置管理过程 | D33: =E33*G33 -> 1 | E33: 0.5 | G33: 2
C34: 审核领导作用 | D34: =E34*G34 -> 0.5 | E34: 0.5 | G34: 1
C35: 审核实施基础 | D35: =E35*G35 -> 0.5 | E35: 0.5 | G35: 1
C36: 审核验证与确认-工作产品评审过程 | D36: =E36*G36 -> 0.5 | E36: 0.5 | G36: 1
C37: 审核需求开发与管理 | D37: =E37*G37 -> 1 | E37: 1 | G37: 1
C38: 拟制质量审核报告 | D38: =F38*G38 -> 1 | F38: 0.5 | G38: 2
C39: 合计 | D39: =SUM(D28:D38) -> 11.5
A40: 编码与单元测试阶段 | C40: 软件详细设计说明审核 | D40: =F40*G40 -> 4 | F40: 4 | G40: 1
...

Sheet 其他管理类工作量估计ok
A1: 项目名称 | B1: XXX | D1: 项目编号 | E1: ZDPX03012
A2: 估计人员 | B2: 穆笑岩 | D2: 估计方法 | E2: 经验法
A3: 估计假设和约束条件 | B3: 工作例会、测量等管理类活动工作量的估计，基于公司提供的单次活动工时经验数据、项目周期内预计开展的活动次数及预计参与人数计算所得。公司提供的单次活动工时经验值见《软件估计指南》。
A4: 估计过程
B5: 管理活动 | C5: 工作量（人时） | D5: 活动次数 | E5: 单次活动工时经验值（人时） | F5: 参加人数
A6: 系统分析与设计 | B6: 项目启动会 | C6: =D6*E6*F6 -> 6 | D6: 1 | E6: 2 | F6: 3
B7: 研制任务书研讨会 | C7: =D7*E7*F7 -> 10 | D7: 1 | E7: 2 | F7: 5
B8: 阶段例会 | C8: =D8*E8*F8 -> 4 | D8: 1 | E8: 0.5 | F8: 8
B9: 阶段进度跟踪 | C9: =D9*E9*F9 -> 1 | D9: 1 | E9: 1 | F9: 1
B10: 小结 | C10: =SUM(C6:C9) -> 21
A11: 需求分析阶段 | B11: 测量分析及进度跟踪 | C11: =D11*E11*F11 -> 3 | D11: 3 | E11: 1 | F11: 1
B12: 项目策划例会 | C12: =D12*E12*F12 -> 16 | D12: 1 | E12: 2 | F12: 8
B13: 阶段例会 | C13: =D13*E13*F13 -> 12 | D13: 3 | E13: 0.5 | F13: 8
B14: 小结 | C14: =SUM(C11:C13) -> 31
A15: 软件概要设计阶段 | B15: 阶段策划 | C15: =D15*E15*F15 -> 2 | D15: 1 | E15: 2 | F15: 1
B16: 测量分析与进度跟踪（包括报告拟制） | C16: =D16*E16*F16 -> 2 | D16: 2 | E16: 1 | F16: 1
B17: 阶段例会 | C17: =D17*E17*F17 -> 8 | D17: 2 | E17: 0.5 | F17: 8
B18: 小结 | C18: =SUM(C15:C17) -> 12
A19: 软件基本型详细设计、编码与单元测试阶段 | B19: 阶段策划 | C19: =D19*E19*F19 -> 2 | D19: 1 | E19: 2 | F19: 1
B20: 阶段例会 | C20: =D20*E20*F20 -> 20 | D20: 5 | E20: 0.5 | F20: 8
B21: 测量分析及进度跟踪（包括报告拟制） | C21: =D21*E21*F21 -> 5 | D21: 5 | E21: 1 | F21: 1
B22: 小结 | C22: =SUM(C19:C21) -> 27
A23: 软件正样基本型详细设计、编码与单元测试阶段 | B23: 阶段策划 | C23: =D23*E23*F23 -> 2 | D23: 1 | E23: 2 | F23: 1
B24: 阶段例会 | C24: =D24*E24*F24 -> 28 | D24: 7 | E24: 0.5 | F24: 8
B25: 测量分析及进度跟踪（包括报告拟制） | C25: =D25*E25*F25 -> 7 | D25: 7 | E25: 1 | F25: 1
B26: 小结 | C26: =SUM(C23:C25) -> 37
A27: 配置项测试阶段 | B27: 阶段策划 | C27: =D27*E27*F27 -> 2 | D27: 1 | E27: 2 | F27: 1
B28: 工作例会 | C28: =D28*E28*F28 -> 12 | D28: 3 | E28: 0.5 | F28: 8
B29: 测量分析及进度跟踪（包括报告拟制） | C29: =D29*E29*F29 -> 3 | D29: 3 | E29: 1 | F29: 1
B30: 小结 | C30: =SUM(C27:C29) -> 17
A31: 出厂所检验阶段 | B31: 阶段策划 | C31: =D31*E31*F31 -> 1 | D31: 1 | E31: 1 | F31: 1
B32: 工作例会 | C32: =D32*E32*F32 -> 4 | D32: 1 | E32: 0.5 | F32: 8
B33: 测量分析及进度跟踪（包括报告拟制） | C33: =D33*E33*F33 -> 1 | D33: 1 | E33: 1 | F33: 1
B34: 小结 | C34: =SUM(C31:C33) -> 6
A35: 总计 | C35: =C10+C14+C18+C22+C26+C30+C34 -> 151

Sheet 评审工作量
A1: 项目名称 | C1: XXXXXX | D1: 项目编号 | E1: ZDPX2021163
A2: 估计人员 | C2: 李闯 | D2: 估计方法 | E2: 经验法
A3: 估计假设与约束条件 | C3: 评审活动工作量的估计，基于公司提供的单次活动工时经验数据、评审对象内容、参与评审人数计算所得。公司提供的单次活动工时经验值见《软件估计指南》
A4: 估计过程
A5: 序号 | B5: 评审对象 | C5: 评审参加人数 | D5: 评审时长（小时） | E5: 评审总工时（人时）
A6: 1 | B6: 软件技术方案 | C6: 4 | D6: 2 | E6: =C6*D6 -> 8
A7: 1 | B7: 软件研制任务书 | C7: 5 | D7: 1 | E7: =C7*D7 -> 5
A8: 2 | B8: 软件开发计划 | C8: 8 | D8: 2 | E8: =C8*D8 -> 16
A9: 3 | B9: 质量保证计划
A10: 4 | B10: 配置管理计划
A11: 5 | B11: 测量与分析计划
A12: 6 | B12: 需求规格说明 | C12: 5 | D12: 2 | E12: =C12*D12 -> 10
A13: 7 | B13: 配置项测试计划 | C13: 4 | D13: 0.5 | E13: =C13*D13 -> 2
A14: 8 | B14: 软件概要设计 | C14: 6 | D14: 2 | E14: =C14*D14 -> 12
A15: 9 | B15: 详细设计说明 | C15: 6 | D15: 2 | E15: =C15*D15 -> 12
A16: 10 | B16: 单元测试计划 | C16: 5 | D16: 0.5 | E16: =C16*D16 -> 2.5
A17: 11 | B17: 单元测试说明 | C17: 5 | D17: 1 | E17: =C17*D17 -> 5
A18: 12 | B18: 单元测试报告 | C18: 5 | D18: 1 | E18: =C18*D18 -> 5
A19: 13 | B19: 配置项测试说明 | C19: 5 | D19: 2 | E19: =C19*D19 -> 10
A20: 14 | B20: 配置项测试报告 | C20: 5 | D20: 1 | E20: =C20*D20 -> 5
A21: 15 | B21: 出厂所检验大纲 | C21: 7 | D21: 1 | E21: =C21*D21 -> 7
A22: 16 | B22: 出厂所检验报告 | C22: 7 | D22: 1 | E22: =C22*D22 -> 7
A23: 总计 | E23: =SUM(E6:E22) -> 106.5

Sheet 规模估计结果报告
A1: 项目名称 | C1: XXXXXX | G1: 项目编号 | H1: ZDPX2021163
A2: 文档规模估计
A3: 估计人员 | C3: ='汇总表(文档相关)ok'!B2 -> 穆笑岩高蕾 张晓丰方小娟 | E3: 估计方法 | G3: ='汇总表(文档相关)ok'!D3 -> 专家估计法
A4: 估计假设和约束条件 | C4: ='汇总表(文档相关)ok'!E4 -> 文档规模估计基于： 1）文档假设采用公司模板编写，页面设置为A4，字号为小四； 2）出所测试文档假设按照配置项测试文档模板编写； 3）文档规模包含封面在内的所有页； 4）参考软件研制任务书的功能数量； 5）参考XXXXXX项目； 6）专家法估计偏差阈值按20%考虑。
A5: 代码规模估计
A6: 估计人员 | C6: ='汇总表(代码相关)'!B2 -> 穆笑岩张晓丰刁鹏孙贵磊 | E6: 估计方法 | G6: ='汇总表(代码相关)'!D3 -> 专家估计法
A7: 估计假设和约束条件 | C7: ='汇总表(代码相关)'!E4 -> 代码规模估计基于： 1）软件源代码的度量按源代码行（LOC）计算，只考虑有效代码行，不考虑注释。 2）软件采用B/S架构，国产化麒麟系统和达梦数据库，代码编写采用C++、Java和JS语言，使用微软VS Code和IDEA开发工具； 3）参考XXXXXX的开发经验和规模经验； 4）参考软件研制任务书中的功能点数量； 5）只对可能发生变化或新增的软件工作产品进行估计。 6）专家法估计偏差阈值按20%考虑。
A8: 估计值列表
A9: 序号 | B9: 估计对象 | E9: 度量单位 | F9: 估计值 | I9: 备注
F10: 总值 | G10: 新增规模 | H10: 重用规模
A11: 1 | B11: ='汇总表(文档相关)ok'!B8 -> 软件开发计划 | E11: ='汇总表(文档相关)ok'!F8 -> 页 | F11: ='汇总表(文档相关)ok'!M8 -> 35 | G11: =ROUND((文档规模及工作量估计ok!H8+文档规模及工作量估计ok!T8+文档规模及工作量估计ok!H50+文档规模及工作量估计ok!T50)/4,0) -> 35 | H11: =ROUND((文档规模及工作量估计ok!J8+文档规模及工作量估计ok!V8+文档规模及工作量估计ok!J50+文档规模及工作量估计ok!V50)/4,0) -> 0
A12: 2 | B12: ='汇总表(文档相关)ok'!B9 -> 软件质量保证计划 | E12: ='汇总表(文档相关)ok'!F9 -> 页 | F12: ='汇总表(文档相关)ok'!M9 -> 16 | G12: =ROUND((文档规模及工作量估计ok!H9+文档规模及工作量估计ok!T9+文档规模及工作量估计ok!H51+文档规模及工作量估计ok!T51)/4,0) -> 16 | H12: =ROUND((文档规模及工作量估计ok!J9+文档规模及工作量估计ok!V9+文档规模及工作量估计ok!J51+文档规模及工作量估计ok!V51)/4,0) -> 0
A13: 3 | B13: ='汇总表(文档相关)ok'!B10 -> 软件配置管理计划 | E13: ='汇总表(文档相关)ok'!F10 -> 页 | F13: ='汇总表(文档相关)ok'!M10 -> 14 | G13: =ROUND((文档规模及工作量估计ok!H10+文档规模及工作量估计ok!T10+文档规模及工作量估计ok!H52+文档规模及工作量估计ok!T52)/4,0) -> 14 | H13: =ROUND((文档规模及工作量估计ok!J10+文档规模及工作量估计ok!V10+文档规模及工作量估计ok!J52+文档规模及工作量估计ok!V52)/4,0) -> 0
A14: 4 | B14: ='汇总表(文档相关)ok'!B11 -> 测量与分析计划 | E14: ='汇总表(文档相关)ok'!F11 -> 页 | F14: ='汇总表(文档相关)ok'!M11 -> 11 | G14: =ROUND((文档规模及工作量估计ok!H11+文档规模及工作量估计ok!T11+文档规模及工作量估计ok!H53+文档规模及工作量估计ok!T53)/4,0) -> 11 | H14: =ROUND((文档规模及工作量估计ok!J11+文档规模及工作量估计ok!V11+文档规模及工作量估计ok!J53+文档规模及工作量估计ok!V53)/4,0) -> 0
A15: 5 | B15: ='汇总表(文档相关)ok'!B12 -> 需求规格说明 | E15: ='汇总表(文档相关)ok'!F12 -> 页 | F15: ='汇总表(文档相关)ok'!M12 -> 55 | G15: =ROUND((文档规模及工作量估计ok!H12+文档规模及工作量估计ok!T12+文档规模及工作量估计ok!H54+文档规模及工作量估计ok!T54)/4,0) -> 55 | H15: =ROUND((文档规模及工作量估计ok!J12+文档规模及工作量估计ok!V12+文档规模及工作量估计ok!J54+文档规模及工作量估计ok!V54)/4,0) -> 0
A16: 6 | B16: ='汇总表(文档相关)ok'!B13 -> 配置项测试计划 | E16: ='汇总表(文档相关)ok'!F13 -> 页 | F16: ='汇总表(文档相关)ok'!M13 -> 18 | G16: =ROUND((文档规模及工作量估计ok!H13+文档规模及工作量估计ok!T13+文档规模及工作量估计ok!H55+文档规模及工作量估计ok!T55)/4,0) -> 18 | H16: =ROUND((文档规模及工作量估计ok!J14+文档规模及工作量估计ok!V14+文档规模及工作量估计ok!J56+文档规模及工作量估计ok!V56)/4,0) -> 0
A17: 7 | B17: ='汇总表(文档相关)ok'!B14 -> 软件设计说明 | E17: ='汇总表(文档相关)ok'!F14 -> 页 | F17: ='汇总表(文档相关)ok'!M14 -> 90 | G17: =ROUND((文档规模及工作量估计ok!H14+文档规模及工作量估计ok!T14+文档规模及工作量估计ok!H56+文档规模及工作量估计ok!T56)/4,0) -> 90 | H17: =ROUND((文档规模及工作量估计ok!J15+文档规模及工作量估计ok!V15+文档规模及工作量估计ok!J57+文档规模及工作量估计ok!V57)/4,0) -> 0
A18: 8 | B18: ='汇总表(文档相关)ok'!B15 -> 单元测试计划 | E18: ='汇总表(文档相关)ok'!F15 -> 页 | F18: ='汇总表(文档相关)ok'!M15 -> 0 | G18: =ROUND((文档规模及工作量估计ok!H15+文档规模及工作量估计ok!T15+文档规模及工作量估计ok!H57+文档规模及工作量估计ok!T57)/4,0) -> 0 | H18: =ROUND((文档规模及工作量估计ok!J16+文档规模及工作量估计ok!V16+文档规模及工作量估计ok!J58+文档规模及工作量估计ok!V58)/4,0) -> 0
A19: 13 | B19: ='汇总表(文档相关)ok'!B16 -> 单元测试报告 | E19: ='汇总表(文档相关)ok'!F16 -> 页 | F19: ='汇总表(文档相关)ok'!M16 -> 0 | G19: =ROUND((文档规模及工作量估计ok!H16+文档规模及工作量估计ok!T16+文档规模及工作量估计ok!H58+文档规模及工作量估计ok!T58)/4,0) -> 0
A20: 15 | B20: ='汇总表(文档相关)ok'!B17 -> 配置项测试说明 | E20: ='汇总表(文档相关)ok'!F17 -> 页 | F20: ='汇总表(文档相关)ok'!M17 -> 43 | G20: =ROUND((文档规模及工作量估计ok!H17+文档规模及工作量估计ok!T17+文档规模及工作量估计ok!H59+文档规模及工作量估计ok!T59)/4,0) -> 43
A21: 16 | B21: ='汇总表(文档相关)ok'!B18 -> 配置项测试报告 | E21: ='汇总表(文档相关)ok'!F18 -> 页 | F21: ='汇总表(文档相关)ok'!M18 -> 73 | G21: =ROUND((文档规模及工作量估计ok!H18+文档规模及工作量估计ok!T18+文档规模及工作量估计ok!H60+文档规模及工作量估计ok!T60)/4,0) -> 73
A22: 17 | B22: ='汇总表(文档相关)ok'!B19 -> 用户手册 | E22: ='汇总表(文档相关)ok'!F19 -> 页 | F22: ='汇总表(文档相关)ok'!M19 -> 30 | G22: =ROUND((文档规模及工作量估计ok!H19+文档规模及工作量估计ok!T19+文档规模及工作量估计ok!H61+文档规模及工作量估计ok!T61)/4,0) -> 30
A23: 20 | B23: ='汇总表(文档相关)ok'!B20 -> 研制总结报告 | E23: ='汇总表(文档相关)ok'!F20 -> 页 | F23: ='汇总表(文档相关)ok'!M20 -> 0 | G23: =ROUND((文档规模及工作量估计ok!H20+文档规模及工作量估计ok!T20+文档规模及工作量估计ok!H62+文档规模及工作量估计ok!T62)/4,0) -> 0
A25: 21 | B25: ='汇总表(代码相关)'!C8 -> 1 | E25: 行 | F25: ='汇总表(代码相关)'!O8 -> 1950 | G25: =ROUND((代码规模及工作量估计!H32+代码规模及工作量估计!T32+代码规模及工作量估计!H8+代码规模及工作量估计!T8)/4,0) -> 1950 | H25: =F25-G25 -> 0
A26: 22 | B26: ='汇总表(代码相关)'!C9 -> 2 | E26: 行 | F26: ='汇总表(代码相关)'!O9 -> 8500 | G26: =ROUND((代码规模及工作量估计!H33+代码规模及工作量估计!T33+代码规模及工作量估计!H9+代码规模及工作量估计!T9)/4,0) -> 8500 | H26: =F26-G26 -> 0
A27: 22 | B27: ='汇总表(代码相关)'!C10 -> 3 | E27: 行 | F27: ='汇总表(代码相关)'!O10 -> 13500 | G27: =ROUND((代码规模及工作量估计!H34+代码规模及工作量估计!T34+代码规模及工作量估计!H10+代码规模及工作量估计!T10)/4,0) -> 13500 | H27: =F27-G27 -> 0
A28: 23 | B28: ='汇总表(代码相关)'!C11 -> 4 | E28: 行 | F28: ='汇总表(代码相关)'!O11 -> 3825 | G28: =ROUND((代码规模及工作量估计!H35+代码规模及工作量估计!T35+代码规模及工作量估计!H11+代码规模及工作量估计!T11)/4,0) -> 3825 | H28: =F28-G28 -> 0
A29: 总计
A30: 文档规模 | E30: 页 | F30: =SUM(F11:F23) -> 385 | G30: =SUM(G11:G23) -> 385 | H30: =SUM(H11:H23) -> 0
A31: 代码规模 | E31: 行 | F31: =SUM(F25:F28) -> 27775 | G31: =SUM(G25:G28) -> 27775 | H31: =SUM(H25:H28) -> 0
A32: 说明： 1）总值=新增规模+重用规模； 2）当估计方法为专家估计法时，总值一栏取自估计汇总表中的取整后估计值； 3）规模的度量单位为“行”（代码）或“页”（文档）； 4）估计对象中，各软件模块应能对应到软件研制任务书中的功能点； 5）重用包括在原有基础上修改使用和直接使用。

Sheet 工作量估计结果报告
A1: 项目名称 | B1: XXXXXX | E1: 项目编号 | G1: ZDPX2021163
A2: 估计假设和约束条件 | C2: ='汇总表(文档相关)ok'!E5 -> 文档编写工作量和合格性测试工作量基于： 1）文档编写人员均有同类文档的编写经验，掌握438C军用软件文档编写要求； 2）参考文档估计规模； 3）参考XXXXXX项目； 4）专家法估计偏差阈值按20%考虑。
C3: ='汇总表(代码相关)'!E5 -> 编码、单元测试及软件BUG修改的工作量估计基于： 1）编码人员均有仿真类和评估类项目的开发经验，且熟悉B/S架构的开发模式； 2）参考XXXXXX和XXXXXX中期评估项目的开发经验和规模经验； 3）参考代码估计规模； 4）专家法估计偏差阈值按20%考虑。
C4: =配置管理工作量估计ok!B3 -> 配置管理活动工作量的估计，基于公司提供的单次活动工时经验数据、项目周期内预计开展的活动次数及配置活动内容计算所得。公司提供的单次活动工时经验值见《软件估计指南》
C5: =质量保证工作量估计ok!C3 -> 质量保证活动工作量的估计，基于公司提供的单次活动工时经验数据、项目周期内预计开展的质量活动次数计算所得。公司提供的单次活动工时经验值见《软件估计指南》。
C6: =其他管理类工作量估计ok!B3 -> 工作例会、测量等管理类活动工作量的估计，基于公司提供的单次活动工时经验数据、项目周期内预计开展的活动次数及预计参与人数计算所得。公司提供的单次活动工时经验值见《软件估计指南》。
C7: =评审工作量!C3 -> 评审活动工作量的估计，基于公司提供的单次活动工时经验数据、评审对象内容、参与评审人数计算所得。公司提供的单次活动工时经验值见《软件估计指南》
A8: 活动类别 | B8: 估计对象 | E8: 估计值 | G8: 估计人员 | H8: 估计方法
A9: 工程类 | B9: ='汇总表(文档相关)ok'!B25 -> 需求规格说明编写 | E9: ='汇总表(文档相关)ok'!M25 -> 48 | G9: ='汇总表(文档相关)ok'!$B$2 -> 穆笑岩高蕾 张晓丰方小娟 | H9: 专家法
B10: ='汇总表(文档相关)ok'!B26 -> 配置项测试计划 | E10: ='汇总表(文档相关)ok'!M26 -> 6 | G10: ='汇总表(文档相关)ok'!$B$2 -> 穆笑岩高蕾 张晓丰方小娟 | H10: 专家法
B11: ='汇总表(文档相关)ok'!B27 -> 软件设计说明编写 | E11: ='汇总表(文档相关)ok'!M27 -> 96 | G11: ='汇总表(文档相关)ok'!$B$2 -> 穆笑岩高蕾 张晓丰方小娟 | H11: 专家法
B12: ='汇总表(文档相关)ok'!B28 -> 单元测试计划编写 | E12: ='汇总表(文档相关)ok'!M28 -> 6 | G12: ='汇总表(文档相关)ok'!$B$2 -> 穆笑岩高蕾 张晓丰方小娟 | H12: 专家法
B13: ='汇总表(文档相关)ok'!#REF! -> #REF! | E13: ='汇总表(文档相关)ok'!#REF! -> #REF! | G13: ='汇总表(文档相关)ok'!$B$2 -> 穆笑岩高蕾 张晓丰方小娟 | H13: 专家法
B14: ='汇总表(文档相关)ok'!#REF! -> #REF! | E14: ='汇总表(文档相关)ok'!#REF! -> #REF! | G14: ='汇总表(文档相关)ok'!$B$2 -> 穆笑岩高蕾 张晓丰方小娟 | H14: 专家法
B15: ='汇总表(文档相关)ok'!#REF! -> #REF! | E15: ='汇总表(文档相关)ok'!#REF! -> #REF! | G15: ='汇总表(文档相关)ok'!$B$2 -> 穆笑岩高蕾 张晓丰方小娟 | H15: 专家法
B16: ='汇总表(文档相关)ok'!#REF! -> #REF! | E16: ='汇总表(文档相关)ok'!#REF! -> #REF! | G16: ='汇总表(文档相关)ok'!$B$2 -> 穆笑岩高蕾 张晓丰方小娟 | H16: 专家法
B17: ='汇总表(文档相关)ok'!B29 -> 单元测试报告编写 | E17: ='汇总表(文档相关)ok'!M29 -> 6 | G17: ='汇总表(文档相关)ok'!$B$2 -> 穆笑岩高蕾 张晓丰方小娟 | H17: 专家法
B18: ='汇总表(文档相关)ok'!#REF! -> #REF! | E18: ='汇总表(文档相关)ok'!#REF! -> #REF! | G18: ='汇总表(文档相关)ok'!$B$2 -> 穆笑岩高蕾 张晓丰方小娟 | H18: 专家法
B19: ='汇总表(文档相关)ok'!B30 -> 配置项测试说明编写 | E19: ='汇总表(文档相关)ok'!M30 -> 40 | G19: ='汇总表(文档相关)ok'!$B$2 -> 穆笑岩高蕾 张晓丰方小娟 | H19: 专家法
B20: ='汇总表(文档相关)ok'!B31 -> 配置项测试报告编写 | E20: ='汇总表(文档相关)ok'!M31 -> 8 | G20: ='汇总表(文档相关)ok'!$B$2 -> 穆笑岩高蕾 张晓丰方小娟 | H20: 专家法
B21: ='汇总表(文档相关)ok'!B32 -> 用户手册编写 | E21: ='汇总表(文档相关)ok'!M32 -> 20 | G21: ='汇总表(文档相关)ok'!$B$2 -> 穆笑岩高蕾 张晓丰方小娟 | H21: 专家法
B22: ='汇总表(文档相关)ok'!#REF! -> #REF! | E22: ='汇总表(文档相关)ok'!#REF! -> #REF! | G22: ='汇总表(文档相关)ok'!$B$2 -> 穆笑岩高蕾 张晓丰方小娟 | H22: 专家法
B23: ='汇总表(文档相关)ok'!#REF! -> #REF! | E23: ='汇总表(文档相关)ok'!#REF! -> #REF! | G23: ='汇总表(文档相关)ok'!$B$2 -> 穆笑岩高蕾 张晓丰方小娟 | H23: 专家法
B24: ='汇总表(文档相关)ok'!B33 -> 研制总结报告编写 | E24: ='汇总表(文档相关)ok'!M33 -> 24 | G24: ='汇总表(文档相关)ok'!$B$2 -> 穆笑岩高蕾 张晓丰方小娟 | H24: 专家法
B25: ='汇总表(文档相关)ok'!B34 -> 执行合格性测试 | E25: ='汇总表(文档相关)ok'!M34 -> 48 | G25: ='汇总表(文档相关)ok'!$B$2 -> 穆笑岩高蕾 张晓丰方小娟 | H25: 专家法
B26: ='汇总表(文档相关)ok'!B35 -> 执行单元测试 | E26: ='汇总表(文档相关)ok'!M35 -> 36 | G26: ='汇总表(文档相关)ok'!$B$2 -> 穆笑岩高蕾 张晓丰方小娟 | H26: 专家法
B27: ='汇总表(代码相关)'!B12 -> 1代码实现 | E27: ='汇总表(代码相关)'!O12 -> 49 | G27: ='汇总表(代码相关)'!$B$2 -> 穆笑岩张晓丰刁鹏孙贵磊 | H27: 专家法
B28: ='汇总表(代码相关)'!B13 -> 2代码实现 | E28: ='汇总表(代码相关)'!O13 -> 142 | G28: ='汇总表(代码相关)'!$B$2 -> 穆笑岩张晓丰刁鹏孙贵磊 | H28: 专家法
B29: ='汇总表(代码相关)'!B14 -> 3代码实现 | E29: ='汇总表(代码相关)'!O14 -> 225 | G29: ='汇总表(代码相关)'!$B$2 -> 穆笑岩张晓丰刁鹏孙贵磊 | H29: 专家法
B30: ='汇总表(代码相关)'!B15 -> 4代码实现 | E30: ='汇总表(代码相关)'!O15 -> 64 | G30: ='汇总表(代码相关)'!$B$2 -> 穆笑岩张晓丰刁鹏孙贵磊 | H30: 专家法
B31: ='汇总表(代码相关)'!#REF! -> #REF! | E31: ='汇总表(代码相关)'!#REF! -> #REF! | G31: ='汇总表(代码相关)'!$B$2 -> 穆笑岩张晓丰刁鹏孙贵磊 | H31: 专家法
B32: ='汇总表(代码相关)'!#REF! -> #REF! | E32: ='汇总表(代码相关)'!#REF! -> #REF! | G32: ='汇总表(代码相关)'!$B$2 -> 穆笑岩张晓丰刁鹏孙贵磊 | H32: 专家法
B33: ='汇总表(代码相关)'!#REF! -> #REF! | E33: ='汇总表(代码相关)'!#REF! -> #REF! | G33: ='汇总表(代码相关)'!$B$2 -> 穆笑岩张晓丰刁鹏孙贵磊 | H33: 专家法
B34: ='汇总表(代码相关)'!#REF! -> #REF! | E34: ='汇总表(代码相关)'!#REF! -> #REF! | G34: ='汇总表(代码相关)'!$B$2 -> 穆笑岩张晓丰刁鹏孙贵磊 | H34: 专家法
B35: ='汇总表(代码相关)'!#REF! -> #REF! | E35: ='汇总表(代码相关)'!#REF! -> #REF! | G35: ='汇总表(代码相关)'!$B$2 -> 穆笑岩张晓丰刁鹏孙贵磊 | H35: 专家法
B36: ='汇总表(代码相关)'!B16 -> 合格性测试bug修改 | E36: ='汇总表(代码相关)'!O16 -> 39 | G36: ='汇总表(代码相关)'!$B$2 -> 穆笑岩张晓丰刁鹏孙贵磊 | H36: 专家法
B37: ='汇总表(代码相关)'!#REF! -> #REF! | E37: ='汇总表(代码相关)'!#REF! -> #REF! | G37: ='汇总表(代码相关)'!$B$2 -> 穆笑岩张晓丰刁鹏孙贵磊 | H37: 专家法
B38: 合计 | E38: =SUM(E9:E37) -> #REF!
A39: 项目策划类 | B39: ='汇总表(文档相关)ok'!B21:E21 -> 软件开发计划编写 | E39: ='汇总表(文档相关)ok'!M21 -> 12 | G39: ='汇总表(文档相关)ok'!B2 -> 穆笑岩高蕾 张晓丰方小娟 | H39: 专家法
B40: ='汇总表(文档相关)ok'!B22:E22 -> 软件质量保证计划编写 | E40: ='汇总表(文档相关)ok'!M22 -> 6 | G40: ='汇总表(文档相关)ok'!B2 -> 穆笑岩高蕾 张晓丰方小娟 | H40: 专家法
...
