Workbook

Sheet 项目信息
A1: 项目名称 | B1: 项目代号 | C1: 项目组长 | D1: 配置管理员 | E1: 质量管理员 | F1: 估计轮次 | G1: 文档估计人1 | H1: 文档估计人2 | I1: 文档估计人3 | J1: 文档估计人4 | K1: 代码估计人1 | L1: 代码估计人2 | M1: 代码估计人3 | N1: 代码估计人4 | O1: CM估计人 | P1: QA估计人 | Q1: 管理估计人 | R1: 评审估计人 | S1: 项目组成员 (逗号分隔)
A2: 相控阵数字样机软件 | B2: 03046 | C2: 赵要浦 | D2: 方小娟 | E2: 高蕾 | F2: 1 | G2: 赵要浦 | H2: 方小娟 | I2: 刁鹏 | J2: 高蕾 | K2: 赵要浦 | L2: 刁鹏 | M2: 时起志 | N2: 邢阳 | O2: 方小娟 | P2: 高蕾 | Q2: 赵要浦 | R2: 赵要浦 | S2: 刁鹏,方小娟,高蕾,时起志,赵要浦,吴丹

Sheet 项目进度计划
A1: WBS | B1: 任务名称 | C1: 计划开始时间 | D1: 计划完成时间 | E1: 关联配置项 | F1: 工期(天) | G1: 工作量(人时) | H1: 资源名称 (逗号分隔)
A2: 1 | B2: 系统分析与设计 | C2: 46006 | D2: 46017 | F2: 10 | G2: 57
A3: 1.1 | B3: 软件工程活动 | C3: 46008 | D3: 46014 | F3: 5 | G3: 32
A4: 1.1.1 | B4: 顾客需求开发与沟通 | C4: 46008 | D4: 46008 | F4: 1 | G4: 4 | H4: 赵要浦
A5: 1.1.2 | B5: 软件研制任务书研讨会 | C5: 46009 | D5: 46009 | F5: 1 | G5: 10 | H5: 刁鹏,方小娟,高蕾,哈金,时起志,赵要浦
A6: 1.1.3 | B6: 软件研制任务书编写 | C6: 46010 | D6: 46014 | F6: 3 | G6: 18 | H6: 赵要浦
A7: 1.2 | B7: 评审活动 | C7: 46016 | D7: 46016 | F7: 1 | G7: 10
A8: 1.2.1 | B8: 评审软件研制任务书 | C8: 46016 | D8: 46016 | F8: 1 | G8: 10 | H8: 方小娟,高蕾,哈金,刘喻,赵要浦,刁鹏,时起志
A9: 1.3 | B9: 项目监控活动 | C9: 46006 | D9: 46017 | F9: 10 | G9: 8
A10: 1.3.1 | B10: 项目启动会 | C10: 46006 | D10: 46006 | F10: 1 | G10: 2 | H10: 赵要浦,方小娟,哈金,刘喻,刘乾勇
A11: 1.3.2 | B11: 阶段例会 | C11: 46017 | D11: 46017 | F11: 1 | G11: 6 | H11: 刁鹏,方小娟,高蕾,时起志,赵要浦,吴丹
A12: 1.4 | B12: 配置管理活动 | C12: 46017 | D12: 46017 | F12: 1 | G12: 2
A13: 1.4.1 | B13: 软件研制任务书入库 | C13: 46017 | D13: 46017 | E13: =配置项清单!B2 -> 相控阵数字样机软件研制任务书 | F13: 1 | G13: 0.5 | H13: 方小娟
A14: 1.4.2 | B14: 发布功能基线 | C14: 46017 | D14: 46017 | F14: 1 | G14: 0.5 | H14: 方小娟
A15: 1.4.3 | B15: 配置状态纪实 | C15: 46017 | D15: 46017 | F15: 1 | G15: 0.5 | H15: 方小娟
A16: 1.4.4 | B16: 配置管理报告 | C16: 46017 | D16: 46017 | F16: 1 | G16: 0.5 | H16: 方小娟
A17: 1.5 | B17: 质量保证活动 | C17: 46015 | D17: 46017 | F17: 3 | G17: 4
A18: 1.5.1 | B18: 审核软件研制任务书 | C18: 46015 | D18: 46015 | F18: 1 | G18: 2 | H18: 高蕾
A19: 1.5.2 | B19: 审核需求开发与管理 | C19: 46016 | D19: 46016 | F19: 1 | G19: 0.5 | H19: 高蕾
A20: 1.5.3 | B20: 审核验证与确认-工作产品评审 | C20: 46016 | D20: 46016 | F20: 1 | G20: 0.5 | H20: 高蕾
A21: 1.5.4 | B21: 审核配置管理 | C21: 46017 | D21: 46017 | F21: 1 | G21: 0.5 | H21: 高蕾
A22: 1.5.5 | B22: 拟制质量审核报告 | C22: 46017 | D22: 46017 | F22: 1 | G22: 0.5 | H22: 高蕾
A23: 1.6 | B23: 需求管理 | C23: 46016 | D23: 46016 | F23: 1 | G23: 1
A24: 1.6.1 | B24: 需求追踪关系检查确认及需管报告编写 | C24: 46016 | D24: 46016 | F24: 1 | G24: 1 | H24: 赵要浦
A25: 2 | B25: 需求分析阶段 | C25: 46020 | D25: 46045 | F25: 19 | G25: 139.5
A26: 2.1 | B26: 策划活动 | C26: 46020 | D26: 46027 | F26: 5 | G26: 53
A27: 2.1.1 | B27: 项目策划会 | C27: 46020 | D27: 46020 | F27: 1 | G27: 5 | H27: 刁鹏,方小娟,高蕾,哈金,时起志,赵要浦
A28: 2.1.2 | B28: 编写软件开发计划（包含项目估算） | C28: 46021 | D28: 46027 | F28: 4 | G28: 30 | H28: 方小娟,高蕾,哈金,时起志,赵要浦,刁鹏
A29: 2.1.3 | B29: 编写测量与分析计划 | C29: 46021 | D29: 46022 | F29: 2 | G29: 6 | H29: 赵要浦
A30: 2.1.4 | B30: 编写质量保证计划 | C30: 46021 | D30: 46021 | F30: 1 | G30: 6 | H30: 高蕾
A31: 2.1.5 | B31: 编写配置管理计划 | C31: 46021 | D31: 46021 | F31: 1 | G31: 6 | H31: 方小娟
A32: 2.2 | B32: 软件工程活动 | C32: 46030 | D32: 46042 | F32: 9 | G32: 36
A33: 2.2.1 | B33: 编写软件需求规格说明 | C33: 46030 | D33: 46036 | F33: 5 | G33: 30 | H33: 赵要浦
A34: 2.2.2 | B34: 编写合格性测试计划 | C34: 46042 | D34: 46042 | F34: 1 | G34: 6 | H34: 吴丹
A35: 2.3 | B35: 评审活动 | C35: 46029 | D35: 46044 | F35: 12 | G35: 22
A36: 2.3.1 | B36: 评审软件开发计划等 | C36: 46029 | D36: 46029 | F36: 1 | G36: 12 | H36: 刁鹏,方小娟,高蕾,哈金,刘喻,时起志,吴丹,赵要浦
A37: 2.3.2 | B37: 评审软件需求规格说明 | C37: 46041 | D37: 46041 | F37: 1 | G37: 8 | H37: 高蕾,哈金,时起志,吴丹,赵要浦
A38: 2.3.3 | B38: 评审合格性测试计划 | C38: 46044 | D38: 46044 | F38: 1 | G38: 2 | H38: 高蕾,时起志,吴丹,赵要浦
A39: 2.4 | B39: 项目监控活动 | C39: 46034 | D39: 46045 | F39: 10 | G39: 14
A40: 2.4.1 | B40: 双周进度跟踪 | C40: 46034 | D40: 46034 | F40: 1 | G40: 1 | H40: 赵要浦
...

Sheet 配置项清单
A1: 序号 | B1: 配置项名称 | C1: 配置项标识 | D1: 版本 | E1: 类型 (文档/代码/其他) | F1: 实际页数 (仅文档类填写) | G1: 所属阶段WBS
A2: 1 | B2: 相控阵数字样机软件研制任务书 | C2: ZDPX03046/0.0-YZRW | D2: V1.0 | E2: 文档 | F2: 12 | G2: =项目进度计划!A2 -> 1
A3: 2 | B3: 相控阵数字样机软件外包产品技术协议 | C3: ZDPX03046/0.0-JSXY | D3: V1.0 | E3: 文档 | F3: 9 | G3: =G2 -> 1
A4: 3 | B4: 相控阵数字样机软件开发计划 | C4: ZDPX03046/0.0-KFJH | D4: V1.0 | E4: 文档 | F4: 31 | G4: 2
A5: 4 | B5: 相控阵数字样机软件测量分析计划 | C5: ZDPX03046/0.0-CLJH | D5: V1.0 | E5: 文档 | F5: 11 | G5: 2
A6: 5 | B6: 相控阵数字样机软件质量保证计划 | C6: ZDPX03046/0.0-ZBJH | D6: V1.0 | E6: 文档 | F6: 16 | G6: 2
A7: 6 | B7: 相控阵数字样机软件配置管理计划 | C7: ZDPX03046/0.0-PGJH | D7: V1.0 | E7: 文档 | F7: 15 | G7: 2
A8: 7 | B8: 相控阵数字样机软件需求规格说明 | C8: ZDPX03046/0.0-RJXG | D8: V1.0 | E8: 文档 | F8: 36 | G8: 2
A9: 8 | B9: 相控阵数字样机软件设计说明 | C9: ZDPX03046/0.0-RJSJ | D9: V1.0 | E9: 文档 | F9: 81 | G9: 3
A10: 9 | B10: 相控阵数字样机软件接口设计说明 | C10: ZDPX03046/0.0-RJJK | D10: V1.0 | E10: 文档 | F10: 8 | G10: 3
A11: 10 | B11: 相控阵数字样机软件单元测试计划 | C11: ZDPX03046/0.0-DCJH | D11: V1.0 | E11: 文档 | F11: 17 | G11: 3
A12: 11 | B12: 相控阵数字样机软件单元测试报告 | C12: ZDPX03046/0.0-DCBG | D12: V1.0 | E12: 文档 | F12: 12 | G12: 4
A13: 12 | B13: 相控阵数字样机软件用户手册 | C13: ZDPX03046/0.0-RJSC | D13: V1.0 | E13: 文档 | F13: 77 | G13: 5
A14: 13 | B14: 相控阵数字样机软件测试计划 | C14: ZDPX03046/0.0-HCJH | D14: V1.0 | E14: 文档 | F14: 13 | G14: 2
A15: 14 | B15: 相控阵数字样机软件测试说明 | C15: ZDPX03046/0.0-HCSM | D15: V1.0 | E15: 文档 | F15: 33 | G15: 6
... A17: 16 | B17: 相控阵数字样机软件研制总结报告 | C17: ZDPX03046/0.0-YZBG | D17: V1.0 | E17: 文档 | F17: 28 | G17: 7
A18: 17 | B18: 相控阵数字样机软件源代码 | C18: ZDPX03046/0.0-SRC | D18: V0.0.3 | E18: 代码
A19: 18 | B19: 相控阵数字样机软件源代码 | C19: ZDPX03046/0.0-SRC | D19: V0.0.4 | E19: 代码
A20: 19 | B20: 相控阵数字样机软件源代码 | C20: ZDPX03046/0.0-SRC | D20: V1.0.0 | E20: 代码
A21: 20 | B21: 相控阵数字样机软件源代码 | C21: ZDPX03046/0.0-SRC | D21: V2.0.0 | E21: 代码
A22: 21 | B22: 相控阵数字样机软件源代码 | C22: ZDPX03046/0.0-SRC | D22: V3.0.0 | E22: 代码
A23: 22 | B23: 相控阵数字样机软件可执行程序 | C23: ZDPX03046/0.0-EXE | D23: V0.0.3 | E23: 代码
A24: 23 | B24: 相控阵数字样机软件可执行程序 | C24: ZDPX03046/0.0-EXE | D24: V0.0.4 | E24: 代码
A25: 24 | B25: 相控阵数字样机软件可执行程序 | C25: ZDPX03046/0.0-EXE | D25: V1.0.0 | E25: 代码
A26: 25 | B26: 相控阵数字样机软件可执行程序 | C26: ZDPX03046/0.0-EXE | D26: V2.0.0 | E26: 代码
A27: 26 | B27: 相控阵数字样机软件可执行程序 | C27: ZDPX03046/0.0-EXE | D27: V3.0.0 | E27: 代码

Sheet 基线组成
A1: 基线名称 | B1: 基线标识 | C1: 基线版本 | D1: 包含配置项名称 | E1: 配置项标识 | F1: 配置项版本
A2: 功能基线 | B2: ZDPX-03046/0.0-BL-GN | C2: V1.0 | D2: =配置项清单!B2 -> 相控阵数字样机软件研制任务书 | E2: =配置项清单!C2 -> ZDPX03046/0.0-YZRW | F2: =配置项清单!D4 -> V1.0
A3: 分配基线 | B3: ZDPX-03046/0.0-BL-FP | C3: V1.0 | D3: =配置项清单!B8 -> 相控阵数字样机软件需求规格说明 | E3: =配置项清单!C8 -> ZDPX03046/0.0-RJXG | F3: =配置项清单!D5 -> V1.0
A4: 产品基线 | B4: ZDPX-03046/0.0-BL-CP | C4: V1.0 | D4: =配置项清单!B2 -> 相控阵数字样机软件研制任务书 | E4: =配置项清单!C2 -> ZDPX03046/0.0-YZRW | F4: =配置项清单!D2 -> V1.0
D5: =配置项清单!B4 -> 相控阵数字样机软件开发计划 | E5: =配置项清单!C4 -> ZDPX03046/0.0-KFJH | F5: =配置项清单!D4 -> V1.0
D6: =配置项清单!B5 -> 相控阵数字样机软件测量分析计划 | E6: =配置项清单!C5 -> ZDPX03046/0.0-CLJH | F6: =配置项清单!D5 -> V1.0
D7: =配置项清单!B6 -> 相控阵数字样机软件质量保证计划 | E7: =配置项清单!C6 -> ZDPX03046/0.0-ZBJH | F7: =配置项清单!D6 -> V1.0
D8: =配置项清单!B7 -> 相控阵数字样机软件配置管理计划 | E8: =配置项清单!C7 -> ZDPX03046/0.0-PGJH | F8: =配置项清单!D7 -> V1.0
D9: =配置项清单!B8 -> 相控阵数字样机软件需求规格说明 | E9: =配置项清单!C8 -> ZDPX03046/0.0-RJXG | F9: =配置项清单!D8 -> V1.0
D10: =配置项清单!B9 -> 相控阵数字样机软件设计说明 | E10: =配置项清单!C9 -> ZDPX03046/0.0-RJSJ | F10: =配置项清单!D9 -> V1.0
D11: =配置项清单!B10 -> 相控阵数字样机软件接口设计说明 | E11: =配置项清单!C10 -> ZDPX03046/0.0-RJJK | F11: =配置项清单!D10 -> V1.0
D12: =配置项清单!B11 -> 相控阵数字样机软件单元测试计划 | E12: =配置项清单!C11 -> ZDPX03046/0.0-DCJH | F12: =配置项清单!D11 -> V1.0
D13: =配置项清单!B12 -> 相控阵数字样机软件单元测试报告 | E13: =配置项清单!C12 -> ZDPX03046/0.0-DCBG | F13: =配置项清单!D12 -> V1.0
D14: =配置项清单!B13 -> 相控阵数字样机软件用户手册 | E14: =配置项清单!C13 -> ZDPX03046/0.0-RJSC | F14: =配置项清单!D13 -> V1.0
D15: =配置项清单!B14 -> 相控阵数字样机软件测试计划 | E15: =配置项清单!C14 -> ZDPX03046/0.0-HCJH | F15: =配置项清单!D14 -> V1.0
D16: =配置项清单!B15 -> 相控阵数字样机软件测试说明 | E16: =配置项清单!C15 -> ZDPX03046/0.0-HCSM | F16: =配置项清单!D15 -> V1.0
... D18: =配置项清单!B17 -> 相控阵数字样机软件研制总结报告 | E18: =配置项清单!C17 -> ZDPX03046/0.0-YZBG | F18: =配置项清单!D17 -> V1.0
D19: =配置项清单!B21 -> 相控阵数字样机软件源代码 | E19: =配置项清单!C21 -> ZDPX03046/0.0-SRC | F19: =配置项清单!D21 -> V2.0.0
D20: =配置项清单!B26 -> 相控阵数字样机软件可执行程序 | E20: =配置项清单!C26 -> ZDPX03046/0.0-EXE | F20: =配置项清单!D26 -> V2.0.0
A21: 入所产品基线 | B21: ZDPX-03046/0.0-BL-RSCP | C21: V1.0 | D21: =配置项清单!B2 -> 相控阵数字样机软件研制任务书 | E21: =配置项清单!C2 -> ZDPX03046/0.0-YZRW | F21: =配置项清单!D2 -> V1.0
D22: =配置项清单!B4 -> 相控阵数字样机软件开发计划 | E22: =配置项清单!C4 -> ZDPX03046/0.0-KFJH | F22: =配置项清单!D4 -> V1.0
D23: =配置项清单!B5 -> 相控阵数字样机软件测量分析计划 | E23: =配置项清单!C5 -> ZDPX03046/0.0-CLJH | F23: =配置项清单!D5 -> V1.0
D24: =配置项清单!B6 -> 相控阵数字样机软件质量保证计划 | E24: =配置项清单!C6 -> ZDPX03046/0.0-ZBJH | F24: =配置项清单!D6 -> V1.0
D25: =配置项清单!B7 -> 相控阵数字样机软件配置管理计划 | E25: =配置项清单!C7 -> ZDPX03046/0.0-PGJH | F25: =配置项清单!D7 -> V1.0
D26: =配置项清单!B8 -> 相控阵数字样机软件需求规格说明 | E26: =配置项清单!C8 -> ZDPX03046/0.0-RJXG | F26: =配置项清单!D8 -> V1.0
D27: =配置项清单!B9 -> 相控阵数字样机软件设计说明 | E27: =配置项清单!C9 -> ZDPX03046/0.0-RJSJ | F27: =配置项清单!D9 -> V1.0
D28: =配置项清单!B10 -> 相控阵数字样机软件接口设计说明 | E28: =配置项清单!C10 -> ZDPX03046/0.0-RJJK | F28: =配置项清单!D10 -> V1.0
D29: =配置项清单!B11 -> 相控阵数字样机软件单元测试计划 | E29: =配置项清单!C11 -> ZDPX03046/0.0-DCJH | F29: =配置项清单!D11 -> V1.0
D30: =配置项清单!B12 -> 相控阵数字样机软件单元测试报告 | E30: =配置项清单!C12 -> ZDPX03046/0.0-DCBG | F30: =配置项清单!D12 -> V1.0
D31: =配置项清单!B13 -> 相控阵数字样机软件用户手册 | E31: =配置项清单!C13 -> ZDPX03046/0.0-RJSC | F31: =配置项清单!D13 -> V1.0
D32: =配置项清单!B14 -> 相控阵数字样机软件测试计划 | E32: =配置项清单!C14 -> ZDPX03046/0.0-HCJH | F32: =配置项清单!D14 -> V1.0
D33: =配置项清单!B15 -> 相控阵数字样机软件测试说明 | E33: =配置项清单!C15 -> ZDPX03046/0.0-HCSM | F33: =配置项清单!D15 -> V1.0
... D35: =配置项清单!B17 -> 相控阵数字样机软件研制总结报告 | E35: =配置项清单!C17 -> ZDPX03046/0.0-YZBG | F35: =配置项清单!D17 -> V1.0
D36: =配置项清单!B22 -> 相控阵数字样机软件源代码 | E36: =配置项清单!C22 -> ZDPX03046/0.0-SRC | F36: =配置项清单!D22 -> V3.0.0
D37: =配置项清单!B27 -> 相控阵数字样机软件可执行程序 | E37: =配置项清单!C27 -> ZDPX03046/0.0-EXE | F37: =配置项清单!D27 -> V3.0.0

Sheet 代码模块
A1: 模块序号 | B1: 模块名称 | C1: 实际行数(LOC)
A2: 1 | B2: 阵列显示模块 | C2: 1721
A3: 2 | B3: 算子参数配置模块 | C3: 2092
A4: 3 | B4: 阵列流程执行模块 | C4: =ROUND(7113/2,0) -> 3557
A5: 4 | B5: 流程结果显示模块 | C5: 1887
